Workbook
Name ATS: NAICS!$E$2:$E$12
Name BAM: NAICS!$F$2:$F$12
Name BAM: 'Alt CLINs'!$F$42:$F$52
Name BAM_Code: 'Alt CLINs'!$F$42:$F$52
Name Blank_Table: 'Alt CLINs'!$F$20:$G$20
Name CLIN_Table: 'Alt CLINs'!$C$1:$C$76
Name CSD: NAICS!$G$2:$G$12
Name CSD: 'Alt CLINs'!$F$26:$F$28
Name CSD_Code: 'Alt CLINs'!$F$26:$F$28
Name CSD_CSS: 'Alt CLINs'!$F$25:$F$25
Name CSDCSS_NAICS: 'Alt CLINs'!$F$26:$G$53
Name CSS: NAICS!$H$2:$H$12
Name CSS: 'Alt CLINs'!$F$29:$F$32
Name CSS_Code: 'Alt CLINs'!$F$29:$F$32
Name CSS_FA: 'Alt CLINs'!$F$24
Name CSS_G: 'Alt CLINs'!$A$1:$A$76
Name CSS_Table: 'Alt CLINs'!$F$6:$G$18
Name D_T: NAICS!$I$2:$I$12
Name DandT: NAICS!$I$2:$I$6
Name ES: NAICS!$J$2:$J$12
Name ES: 'Alt CLINs'!$F$34
Name ES_Code: 'Alt CLINs'!$F$34
Name ES_Table: 'Alt CLINs'!$F$22:$G$22
Name FA_Code: 'Alt CLINs'!$F$24:$F$25
Name FA_Table: 'Alt CLINs'!$F$24:$G$25
Name FAlookup: NAICS!$F$15:$F$22
Name FiscalYearProgramYear: NAICS!$O$20:$Q$34
Name M_R: NAICS!$K$2:$K$12
Name MandR: NAICS!$K$2:$K$4
Name PaymentSchedule: NAICS!$Y$1:$Y$193
Name Prime_Sub: 'Alt CLINs'!$F$3:$F$4
Name R_D: NAICS!$L$2:$L$12
Name RandD: NAICS!$L$2:$L$4
Name SelectedFY: 'CLINs & Ceiling Rates'!$D$6
Name Site: 'Alt CLINs'!$G$3:$G$4
Name Table_NAICS: 'Alt CLINs'!$F$6:$G$19
Name Valid_NAICS: 'Alt CLINs'!$F$6:$F$19

Sheet Instruction to the CS-HIDE TAB
A1: 1 | B1: v 15.0 - Please HIDE this Instruction Tab before releasing or publishing the file. This Attachment B is set up to allow up to 150 CLINs and 150 FFP deliverable lines. Any lines that are not needed should be hidden. Please hide and unhide the rows as appropriate. It is NOT recommended to add or delete rows or columns unless it is specifically indicated because it will mess up the formula that is running in the spreadsheet. If adding new rows, please ensure the formula and everything else on the spreadsheet gets updated. Color Keys: White Cell - Data entry by the CS Yellow Cell - Data entry by the CS for checking against the IGCE but must be left blank for entry by the offeror (unless AHR). Colored Cell - Running Formula, not recommended to change.
A2: 2 | B2: "Instructions" tab is set up for the vendors to select the FA and NAICS code. - Please note, FA must be selected for the CLINs to show up.
A3: 3 | B3: Input data only into the "CLINs & Ceiling Rates" in the white colored cells (see image to the right) - Update the PA number at the top left corner. This will update all the other tabs in the file. - celll "C5" wil pull the FA selected from the "Instructions" tab. The CLINs will populate only when the FA is selected. - Select the FY in the cell E5 (Format example: FY2020) - Input the Roles in column B (copy and paste the text from the IGCE) - Input the eFAST Labor Category in column C. If the CLIN doesn't show up correctly in column E, then the input is incorrect (maybe extra space or lack of "/") - Select the location in column D - Enter in the maximum option period number in cell B163. If there are no option years, select number zero. - Select the "Year" or "Period" in cell B164. Recommended to leave it as "Period". - Select the contract type in cell B165. - Input the travel or other ODC amount in row 168 - 173 per each year. If the Program Office has an ODC description that is different, update the column C to reflect the different discription. It will update the rest of the tabs. - Update the Task Numbers from row 177 to 196 in Column C as appropriate. Update Column D with the funding type if there are more than one color of money involved; if there is only one color of money then leave it blank. - Hide the entire section (row 160-196) once all the info has been entered. This is to prevent duplicate information being shown and creating possible confusion.
A4: 4 | B4: Yellow colored cells in the "CLINs & Ceiling Rates are for the vendor's input.
A5: 5 | B5: Input the hours in the "Labor Loading Matrix" tab in the white colored cells only. - Columns for up to Task 15 has been pre-created. Hide or unhide as needed. - Input hours for each base period and option periods. First table is for the total sum and already has a running total. - Hide any Option Period not in use.
A6: 6 | B6: Check that summary tab shows correct calculation.
A7: 7 | B7: When everything looks correct, hide the "Instruction to the CS" tab.
A8: 8 | B8: Protect every single sheet and lastly protect the workbook.
B10: Updated 6/22/2021

Sheet Instructions
A1: ='CLINs & Ceiling Rates'!B2 -> eFAST Procurement Action 26-017-C8
A3: INSTRUCTIONS: Attachment B – Supplies and Services Prices
A5: =CONCATENATE("Entire Task Order is to be priced as"," ",'CLINs & Ceiling Rates'!C225,".") -> Entire Task Order is to be priced as Time and Materials (T&M).
A7: 1) | B7: Please fill in yellow cells only in each tab. If the offeror alters the spreadsheet, it is their responsibility to insure that all formulas work appropriately.
A9: 2) | B9: Select the eFAST Functional Area (FA) from the drop-down list and self certify an appropriate NAICS Code for that FA in the cell below.
B11: Functional Area | C11: BAM | D11: =IF(C11="","Please select appropriate FA",IF(C11="ATS","Air Transportation Services", IF(C11="BAM","Business Administration Management ",IF(C11="CSD","Computer Systems Development",IF(C11="CSS", "Computer Systems Support",IF(C11="DandT", "Documentation and Training",IF(C11="ES", "Engineering Services",IF(C11="MandR", "Maintenance and Repair", IF(C11="RandD", "Research and Development","Please select appropriate FA"))))))))) -> Business Administration Management
B12: NAICS Code | D12: =IF(C12="","Please select a valid NAICS Code for the FA selected",VLOOKUP(VALUE(C12),NAICS!B1:C41,2,FALSE)) -> Please select a valid NAICS Code for the FA selected
A14: 3) | B14: =IF('CLINs & Ceiling Rates'!C223=0,CONCATENATE("In the CLINs & Ceiling Rates tab, select Prime/Subcontractor mix in Column E, enter subcontractor name in the appropriate CLIN row under Column F, enter Base ",'CLINs & Ceiling Rates'!C224," ","(",VLOOKUP(SelectedFY,FiscalYearProgramYear,3,FALSE),"/","PY",VLOOKUP(SelectedFY,FiscalYearProgramYear,2,FALSE),")"," ","J-4 Ceiling Labor Rates in Column H for each eFAST CLIN listed in Column G."),CONCATENATE("In the CLINs & Ceiling Rates tab, select Prime / Subcontractor mix in Column E, enter subcontractor name in the appropriate CLIN row under Column F, enter Base ",'CLINs & Ceiling Rates'!C224," ","(",VLOOKUP(SelectedFY,FiscalYearProgramYear,3,FALSE),"/","PY",VLOOKUP(SelectedFY,FiscalYearProgramYear,2,FALSE),")"," ","J-4 Ceiling Labor Rates in Column H for each eFAST CLIN listed in Column G and the proposed annual escalation for Option ",'CLINs & Ceiling Rates'!C224, " 1 - ",'CLINs & Ceiling Rates'!C223," ","labor rates where indicated at the top of Columns J, L, N, and P.")) -> In the CLINs & Ceiling Rates tab, select Prime / Subcontractor mix in Column E, enter subcontractor name in the appropriate CLIN row under Column F, enter Base Period (FY26/PY17) J-4 Ceiling Labor Rates in Column H for each eFAST CLIN listed in Column G and the proposed annual escalation for Option Period 1 - 4 labor rates where indicated at the top of Columns J, L, N, and P.
A16: 4) | B16: =CONCATENATE("The Labor Loading Matrix tab provides hours per ",'CLINs & Ceiling Rates'!C224, " for each CLIN in Column C. These hours are broken down by SOW Task in Columns G through I.") -> The Labor Loading Matrix tab provides hours per Period for each CLIN in Column C. These hours are broken down by SOW Task in Columns G through I.
A18: 4) | B18: =VLOOKUP('CLINs & Ceiling Rates'!C225,NAICS!F25:G28,2,FALSE) -> Hide the FFP Tab and hide this instruction line.
A20: 5) | B20: =CONCATENATE("Select the Base ",'CLINs & Ceiling Rates'!C224, " through Option ",'CLINs & Ceiling Rates'!C224," ",'CLINs & Ceiling Rates'!C223," ","tabs to enter labor rate discounts and the Administrative Handling Rate (AHR) applicable to ODCs/Travel. The Summary tab will populate automatically.") -> Select the Base Period through Option Period 4 tabs to enter labor rate discounts and the Administrative Handling Rate (AHR) applicable to ODCs/Travel. The Summary tab will populate automatically.
A22: 6) | B22: =CONCATENATE("Select the Cost Build Up tab to provide cost build up information in Columns E through I. Cost Build Up tab, column J should equal to the corresponding “Discounted Proposed Labor Rate” in the Base ",'CLINs & Ceiling Rates'!C224, " tab column J.") -> Select the Cost Build Up tab to provide cost build up information in Columns E through I. Cost Build Up tab, column J should equal to the corresponding “Discounted Proposed Labor Rate” in the Base Period tab column J.
A24: 7) | B24: If Subcontractor(s) are proposed, they must be identified below and the appropriate button selected to indicate whether the offeror's agreement with the Subcontractor(s) is an STA or a CTA as defined in the MOA. If the agreement type is STA, the Prime and Subcontractor percentages must also be entered below.
G25: (Required if STA is indicated)
B26: NAME(S) OF ALL PROPOSED SUBCONTRACTORS | E26: AGMT TYPE | G26: PRIME % | H26: SUB %

Sheet NAICS
A1: ATS | B1: 238210 | C1: Electrical Contractors and Other Wiring Installation Contractors | E1: ATS | F1: BAM | G1: CSD | H1: CSS | I1: DandT | J1: ES | K1: MandR | L1: RandD | R1: 0905001C | S1: =RIGHT(R1,6) -> 05001C | T1: =LEFT(S1,5) -> 05001 | U1: =RIGHT(T1,3) -> 001 | V1: Program Manager | W1: =U1 -> 001 | Y1: 44166
A2: ATS | B2: 488111 | C2: Air Traffic Control Services | E2: 238210 | F2: 541211 | G2: 541430 | H2: 518210 | I2: 561410 | J2: 541330 | K2: 811212 | L2: 541712 | R2: 0905001G | S2: =RIGHT(R2,6) -> 05001G | T2: =LEFT(S2,5) -> 05001 | U2: =RIGHT(T2,3) -> 001 | V2: Program Manager | W2: =U2 -> 001 | Y2: 44197
A3: ATS | B3: 488119 | C3: Other Airport Operations | E3: 488111 | F3: 541214 | G3: 541511 | H3: 519190 | I3: 611420 | K3: 811213 | L3: 541715 | R3: 0905002C | S3: =RIGHT(R3,6) -> 05002C | T3: =LEFT(S3,5) -> 05002 | U3: =RIGHT(T3,3) -> 002 | V3: Technical Project Manager | W3: =U3 -> 002 | Y3: 44228
A4: ATS | B4: 488190 | C4: Other Support Activities for Air Transportation | E4: 488119 | F4: 541219 | G4: 541512 | H4: 541513 | I4: 611430 | K4: 811219 | L4: 541720 | R4: 0905002G | S4: =RIGHT(R4,6) -> 05002G | T4: =LEFT(S4,5) -> 05002 | U4: =RIGHT(T4,3) -> 002 | V4: Technical Project Manager | W4: =U4 -> 002 | Y4: 44256
A5: ATS | B5: 541310 | C5: Architectural Services | E5: 488190 | F5: 541611 | H5: 541519 | I5: 611512 | R5: 0905003C | S5: =RIGHT(R5,6) -> 05003C | T5: =LEFT(S5,5) -> 05003 | U5: =RIGHT(T5,3) -> 003 | V5: Administrative Project Manager | W5: =U5 -> 003 | Y5: 44287
A6: ATS | B6: 541380 | C6: Testing Laboratories | E6: 541310 | F6: 541612 | I6: 611710 | O6: Contractor site - C | P6: C | R6: 0905003G | S6: =RIGHT(R6,6) -> 05003G | T6: =LEFT(S6,5) -> 05003 | U6: =RIGHT(T6,3) -> 003 | V6: Administrative Project Manager | W6: =U6 -> 003 | Y6: 44317
A7: ATS | B7: 541620 | C7: Environmental Consulting Services | E7: 541380 | F7: 541613 | O7: Government site - G | P7: G | R7: 0905004C | S7: =RIGHT(R7,6) -> 05004C | T7: =LEFT(S7,5) -> 05004 | U7: =RIGHT(T7,3) -> 004 | V7: Task Leader | W7: =U7 -> 004 | Y7: 44348
A8: ATS | B8: 541690 | C8: Other Scientific and Technical Consulting Services | E8: 541620 | F8: 541614 | R8: 0905004G | S8: =RIGHT(R8,6) -> 05004G | T8: =LEFT(S8,5) -> 05004 | U8: =RIGHT(T8,3) -> 004 | V8: Task Leader | W8: =U8 -> 004 | Y8: 44378
A9: ATS | B9: 541990 | C9: All Other Professional, Scientific, and Technical Services | E9: 541690 | F9: 541618 | R9: 0905005C | S9: =RIGHT(R9,6) -> 05005C | T9: =LEFT(S9,5) -> 05005 | U9: =RIGHT(T9,3) -> 005 | V9: Project Control Analyst | W9: =U9 -> 005 | Y9: 44409
A10: ATS | B10: 561210 | C10: Facilities Support Services | E10: 541990 | F10: 561110 | R10: 0905005G | S10: =RIGHT(R10,6) -> 05005G | T10: =LEFT(S10,5) -> 05005 | U10: =RIGHT(T10,3) -> 005 | V10: Project Control Analyst | W10: =U10 -> 005 | Y10: 44440
A11: ATS | B11: 562910 | C11: Remediation Services | E11: 561210 | F11: 561499 | N11: ATS | O11: Air Transportation Services | P11: 1 | R11: 0905006C | S11: =RIGHT(R11,6) -> 05006C | T11: =LEFT(S11,5) -> 05006 | U11: =RIGHT(T11,3) -> 006 | V11: Assoc Scientist/Engineer/Systems Analyst | W11: =U11 -> 006 | Y11: 44470
A12: BAM | B12: 541211 | C12: Offices of Certified Public Accountants | E12: 562910 | F12: 561611 | N12: BAM | O12: Business Administration Management | P12: 2 | R12: 0905006G | S12: =RIGHT(R12,6) -> 05006G | T12: =LEFT(S12,5) -> 05006 | U12: =RIGHT(T12,3) -> 006 | V12: Assoc Scientist/Engineer/Systems Analyst | W12: =U12 -> 006 | Y12: 44501
A13: BAM | B13: 541214 | C13: Payroll Services | N13: CSD | O13: Computer Systems Development | P13: 5 | R13: 0905007C | S13: =RIGHT(R13,6) -> 05007C | T13: =LEFT(S13,5) -> 05007 | U13: =RIGHT(T13,3) -> 007 | V13: Int I Scientist/Engineer/Systems Analyst | W13: =U13 -> 007 | Y13: 44531
A14: BAM | B14: 541219 | C14: Other Accounting Services | N14: CSS | O14: Computer Systems Support | P14: 6 | R14: 0905007G | S14: =RIGHT(R14,6) -> 05007G | T14: =LEFT(S14,5) -> 05007 | U14: =RIGHT(T14,3) -> 007 | V14: Int I Scientist/Engineer/Systems Analyst | W14: =U14 -> 007 | Y14: 44562
A15: BAM | B15: 541611 | C15: Administrative Management and General Management Consulting Services | E15: ATS | F15: ATS | N15: DandT | O15: Documentation and Training | P15: 7 | R15: 0905008C | S15: =RIGHT(R15,6) -> 05008C | T15: =LEFT(S15,5) -> 05008 | U15: =RIGHT(T15,3) -> 008 | V15: Int II Scientist/Engineer/Systems Analyst | W15: =U15 -> 008 | Y15: 44593
A16: BAM | B16: 541612 | C16: Human Resources Consulting Services | E16: BAM | F16: BAM | N16: ES | O16: Engineering Services | P16: 4 | R16: 0905008G | S16: =RIGHT(R16,6) -> 05008G | T16: =LEFT(S16,5) -> 05008 | U16: =RIGHT(T16,3) -> 008 | V16: Int II Scientist/Engineer/Systems Analyst | W16: =U16 -> 008 | Y16: 44621
A17: BAM | B17: 541613 | C17: Marketing Consulting Services | E17: CSD | F17: CSD | N17: MandR | O17: Maintenance and Repair | P17: 8 | R17: 0905009C | S17: =RIGHT(R17,6) -> 05009C | T17: =LEFT(S17,5) -> 05009 | U17: =RIGHT(T17,3) -> 009 | V17: Senior I Scientist/Engineer/Systems Analyst | W17: =U17 -> 009 | Y17: 44652
A18: BAM | B18: 541614 | C18: Process, Physical Distribution, and Logistics Consulting Services | E18: CSS | F18: CSS | N18: RandD | O18: Research and Development | P18: 3 | R18: 0905009G | S18: =RIGHT(R18,6) -> 05009G | T18: =LEFT(S18,5) -> 05009 | U18: =RIGHT(T18,3) -> 009 | V18: Senior I Scientist/Engineer/Systems Analyst | W18: =U18 -> 009 | Y18: 44682
A19: BAM | B19: 541618 | C19: Other Management Consulting Services | E19: D&T | F19: DandT | R19: 0905010C | S19: =RIGHT(R19,6) -> 05010C | T19: =LEFT(S19,5) -> 05010 | U19: =RIGHT(T19,3) -> 010 | V19: Senior Cert Scientist/Engineer/Systems Analyst | W19: =U19 -> 010 | Y19: 44713
A20: BAM | B20: 561110 | C20: Office Administrative Services | E20: ES | F20: ES | O20: FY2019 | P20: 10 | Q20: FY19 | R20: 0905010G | S20: =RIGHT(R20,6) -> 05010G | T20: =LEFT(S20,5) -> 05010 | U20: =RIGHT(T20,3) -> 010 | V20: Senior Cert Scientist/Engineer/Systems Analyst | W20: =U20 -> 010 | Y20: 44743
A21: BAM | B21: 561499 | C21: Other Business Support Services | E21: M&R | F21: MandR | O21: FY2020 | P21: 11 | Q21: FY20 | R21: 0905011C | S21: =RIGHT(R21,6) -> 05011C | T21: =LEFT(S21,5) -> 05011 | U21: =RIGHT(T21,3) -> 011 | V21: Senior II Scientist/Engineer/Systems Analyst | W21: =U21 -> 011 | Y21: 44774
A22: BAM | B22: 561611 | C22: Investigation Services | E22: R&D | F22: RandD | O22: FY2021 | P22: 12 | Q22: FY21 | R22: 0905011G | S22: =RIGHT(R22,6) -> 05011G | T22: =LEFT(S22,5) -> 05011 | U22: =RIGHT(T22,3) -> 011 | V22: Senior II Scientist/Engineer/Systems Analyst | W22: =U22 -> 011 | Y22: 44805
A23: CSD | B23: 541430 | C23: Graphic Design Services | O23: FY2022 | P23: 13 | Q23: FY22 | R23: 0905012C | S23: =RIGHT(R23,6) -> 05012C | T23: =LEFT(S23,5) -> 05012 | U23: =RIGHT(T23,3) -> 012 | V23: Senior PhD Scientist/Engineer/Systems Analyst | W23: =U23 -> 012 | Y23: 44835
A24: CSD | B24: 541511 | C24: Custom Computer Programming Services | G24: Instruction Tab | H24: Each POP Tab | O24: FY2023 | P24: 14 | Q24: FY23 | R24: 0905012G | S24: =RIGHT(R24,6) -> 05012G | T24: =LEFT(S24,5) -> 05012 | U24: =RIGHT(T24,3) -> 012 | V24: Senior PhD Scientist/Engineer/Systems Analyst | W24: =U24 -> 012 | Y24: 44866
A25: CSD | B25: 541512 | C25: Computer Systems Design Services | F25: Time and Materials (T&M) | G25: Hide the FFP Tab and hide this instruction line. | H25: TOTAL T&M HOURS & ESTIMATED LABOR COST | I25: Time and Materials (T&M) | J25: Hide This Table (Rows 159 through 311) | K25: T&M Labor Summary by CLIN | L25: Hide this Table (Rows 158 through 310) | M25: TOTAL MOA CEILING T&M LABOR COST | O25: FY2024 | P25: 15 | Q25: FY24 | R25: 0905013C | S25: =RIGHT(R25,6) -> 05013C | T25: =LEFT(S25,5) -> 05013 | U25: =RIGHT(T25,3) -> 013 | V25: Assoc Computer Scientist/Systems Analyst | W25: =U25 -> 013 | Y25: 44896
A26: CSS | B26: 518210 | C26: Data Processing, Hosting and Related Services | F26: Firm Fixed Price (FFP) | G26: In the Firm Fixed Price tab, please fill in yellow cells only to propose the hours required for the deliverable. | I26: Labor Table | J26: Firm Fixed Price (FFP) | K26: Labor Summary by CLIN | L26: Firm Fixed Price (FFP) Hours and Costs per Deliverable Summary | M26: Delete This Section of the Table (B313 through B319) | O26: FY2025 | P26: 16 | Q26: FY25 | R26: 0905013G | S26: =RIGHT(R26,6) -> 05013G | T26: =LEFT(S26,5) -> 05013 | U26: =RIGHT(T26,3) -> 013 | V26: Assoc Computer Scientist/Systems Analyst | W26: =U26 -> 013 | Y26: 44927
A27: CSS | B27: 519190 | C27: All Other Information Services | F27: Firm Fixed Price / Time and Materials (FFP/T&M) | G27: In the Firm Fixed Price tab, please fill in yellow cells only to propose the hours required for the deliverable. Please look at both the Labor Loading Matrix and Firm Fixed Price tabs to fully understand what work is covered under the FFP versus T&M portions of the task order. | H27: TOTAL T&M HOURS & ESTIMATED LABOR COST | I27: Time and Materials (T&M) | J27: Firm Fixed Price (FFP) | K27: T&M Labor Summary by CLIN | L27: Firm Fixed Price (FFP) Hours and Costs per Deliverable Summary | M27: TOTAL MOA CEILING T&M LABOR COST | O27: FY2026 | P27: 17 | Q27: FY26 | R27: 0905014C | S27: =RIGHT(R27,6) -> 05014C | T27: =LEFT(S27,5) -> 05014 | U27: =RIGHT(T27,3) -> 014 | V27: Int I Computer Scientist/Systems Analyst | W27: =U27 -> 014 | Y27: 44958
A28: CSS | B28: 541513 | C28: Computer Facilities Management Services | F28: Fixed Price Level Of Effort (FP/LOE) | G28: In the FP-LOE tab, please fill in yellow cells only to propose the hours required for the deliverable. | I28: Fixed Price Level Of Effort (FP/LOE) | J28: Hide This Table (Rows 159 through 311) | K28: FP-LOE Labor Summary by CLIN | L28: Hide this Table (Rows 158 through 310) | M28: TOTAL MOA CEILING FP-LOE LABOR COST | O28: FY2027 | P28: 18 | Q28: FY27 | R28: 0905014G | S28: =RIGHT(R28,6) -> 05014G | T28: =LEFT(S28,5) -> 05014 | U28: =RIGHT(T28,3) -> 014 | V28: Int I Computer Scientist/Systems Analyst | W28: =U28 -> 014 | Y28: 44986
A29: CSS | B29: 541519 | C29: Other Computer Related Services | O29: FY2028 | P29: 19 | Q29: FY28 | R29: 0905015C | S29: =RIGHT(R29,6) -> 05015C | T29: =LEFT(S29,5) -> 05015 | U29: =RIGHT(T29,3) -> 015 | V29: Int II Computer Scientist/Systems Analyst | W29: =U29 -> 015 | Y29: 45017
A30: D&T | B30: 561410 | C30: Documentation Preparation Services | F30: Time and Materials (T&M) | G30: TOTAL PROPOSED T&M LABOR COST | H30: Delete This Section of the Table | I30: Delete This Section of the Table | J30: 100 % T&M, This Tab is Not Applicable - Hide This Tab. | K30: NA - Hide | O30: FY2029 | P30: 20 | Q30: FY29 | R30: 0905015G | S30: =RIGHT(R30,6) -> 05015G | T30: =LEFT(S30,5) -> 05015 | U30: =RIGHT(T30,3) -> 015 | V30: Int II Computer Scientist/Systems Analyst | W30: =U30 -> 015 | Y30: 45047
A31: D&T | B31: 611420 | C31: Computer Training | F31: Firm Fixed Price (FFP) | G31: Delete This Section of the Table (C313 through C319) | H31: TOTAL MOA CEILING FFP LABOR COST | I31: TOTAL PROPOSED FFP LABOR COST | J31: FFP cost for each month should be tied to the required quantity indicated in each Period tab. Total FFP cost for each period of performance should equal to the total proposed FFP amount shown in the "Summary" tab. If this is not correct, excel will provide "ERROR" notice right below the "total". | K31: FFP | O31: FY2030 | P31: 21 | Q31: FY30 | R31: 0905016C | S31: =RIGHT(R31,6) -> 05016C | T31: =LEFT(S31,5) -> 05016 | U31: =RIGHT(T31,3) -> 016 | V31: Senior I Computer Scientist/Systems Analyst | W31: =U31 -> 016 | Y31: 45078
A32: D&T | B32: 611430 | C32: Professional & Management Development Training | F32: Firm Fixed Price / Time and Materials (FFP/T&M) | G32: TOTAL PROPOSED T&M LABOR COST | H32: TOTAL MOA CEILING FFP LABOR COST | I32: TOTAL PROPOSED FFP LABOR COST | J32: FFP cost for each month should be tied to the required quantity indicated in each Period tab. Total FFP cost for each period of performance should equal to the total proposed FFP amount shown in the "Summary" tab. If this is not correct, excel will provide "ERROR" notice right below the "total". | K32: FFP | O32: FY2031 | P32: 22 | Q32: FY31 | R32: 0905016G | S32: =RIGHT(R32,6) -> 05016G | T32: =LEFT(S32,5) -> 05016 | U32: =RIGHT(T32,3) -> 016 | V32: Senior I Computer Scientist/Systems Analyst | W32: =U32 -> 016 | Y32: 45108
A33: D&T | B33: 611512 | C33: Flight Training | F33: Fixed Price Level Of Effort (FP/LOE) | G33: TOTAL PROPOSED FP-LOE LABOR COST | H33: Delete This Section of the Table | I33: Delete This Section of the Table | J33: 100 % FP-LOE, This Tab is Not Applicable - Hide This Tab. | K33: NA - Hide | O33: FY2032 | P33: 23 | Q33: FY32 | R33: 0905017C | S33: =RIGHT(R33,6) -> 05017C | T33: =LEFT(S33,5) -> 05017 | U33: =RIGHT(T33,3) -> 017 | V33: Senior Cert Computer Scientist/Systems Analyst | W33: =U33 -> 017 | Y33: 45139
A34: D&T | B34: 611710 | C34: Educational Support Services | O34: FY2033 | P34: 24 | Q34: FY33 | R34: 0905017G | S34: =RIGHT(R34,6) -> 05017G | T34: =LEFT(S34,5) -> 05017 | U34: =RIGHT(T34,3) -> 017 | V34: Senior Cert Computer Scientist/Systems Analyst | W34: =U34 -> 017 | Y34: 45170
A35: ES | B35: 541330 | C35: Engineering Services | R35: 0905018C | S35: =RIGHT(R35,6) -> 05018C | T35: =LEFT(S35,5) -> 05018 | U35: =RIGHT(T35,3) -> 018 | V35: Senior II Computer Scientist/Systems Analyst | W35: =U35 -> 018 | Y35: 45200
A36: M&R | B36: 811212 | C36: Computer and Office Machine Repair and Maintenance | R36: 0905018G | S36: =RIGHT(R36,6) -> 05018G | T36: =LEFT(S36,5) -> 05018 | U36: =RIGHT(T36,3) -> 018 | V36: Senior II Computer Scientist/Systems Analyst | W36: =U36 -> 018 | Y36: 45231
A37: M&R | B37: 811213 | C37: Communication Equipment Repair and Maintenance | R37: 0905019C | S37: =RIGHT(R37,6) -> 05019C | T37: =LEFT(S37,5) -> 05019 | U37: =RIGHT(T37,3) -> 019 | V37: Senior PhD Computer Scientist/Systems Analyst | W37: =U37 -> 019 | Y37: 45261
A38: M&R | B38: 811219 | C38: Other Electronic and Precision Equipment Repair and Maintenance | R38: 0905019G | S38: =RIGHT(R38,6) -> 05019G | T38: =LEFT(S38,5) -> 05019 | U38: =RIGHT(T38,3) -> 019 | V38: Senior PhD Computer Scientist/Systems Analyst | W38: =U38 -> 019 | Y38: 45292
A39: R&D | B39: 541712 | C39: Research and Development in the Physical, Engineering, and Life Sciences (except Biotechnology) (Except Aircraft under the U.S. Industry Title: 1500 size standards in number of employees) | R39: 0905020C | S39: =RIGHT(R39,6) -> 05020C | T39: =LEFT(S39,5) -> 05020 | U39: =RIGHT(T39,3) -> 020 | V39: Assoc IT Analyst | W39: =U39 -> 020 | Y39: 45323
A40: R&D | B40: 541715 | C40: Research and Development in the Physical, Engineering, and Life Sciences (except Nanotechnology and Biotechnology) | R40: 0905020G | S40: =RIGHT(R40,6) -> 05020G | T40: =LEFT(S40,5) -> 05020 | U40: =RIGHT(T40,3) -> 020 | V40: Assoc IT Analyst | W40: =U40 -> 020 | Y40: 45352
...

Sheet Alt CLINs
A1: 905001C | B1: 906001C | C1: Program Manager
A2: 905002C | B2: 906002C | C2: Technical Project Manager
A3: 905003C | B3: 906003C | C3: Administrative Project Manager | F3: Prime | G3: Contractor Site
A4: 905004C | B4: 906004C | C4: Task Leader | F4: Subcontractor | G4: Government Site
A5: 905005C | B5: 906005C | C5: Project Control Analyst
A6: 905006C | B6: 906006C | C6: Assoc Scientist/Engineer/Systems Analyst | F6: 541211 | G6: Offices of Certified Public Accountants
A7: 905007C | B7: 906007C | C7: Int I Scientist/Engineer/Systems Analyst | F7: 541214 | G7: Payroll Services
A8: 905008C | B8: 906008C | C8: Int II Scientist/Engineer/Systems Analyst | F8: 541219 | G8: Other Accounting Services
A9: 905009C | B9: 906009C | C9: Senior I Scientist/Engineer/Systems Analyst | F9: 541430 | G9: Graphic Design Services
A10: 905010C | B10: 906010C | C10: Senior Cert Scientist/Engineer/Systems Analyst | F10: 541511 | G10: Custom Computer Programming Services
A11: 905011C | B11: 906011C | C11: Senior II Scientist/Engineer/Systems Analyst | F11: 541512 | G11: Computer Systems Design Services
A12: 905012C | B12: 906012C | C12: Senior PhD Scientist/Engineer/Systems Analyst | F12: 541611 | G12: Administrative Management and General Management Consulting Services
A13: 905013C | B13: 906013C | C13: Assoc Computer Scientist/Systems Analyst | F13: 541612 | G13: Human Resources Consulting Services
A14: 905014C | B14: 906014C | C14: Int I Computer Scientist/Systems Analyst | F14: 541613 | G14: Marketing Consulting Services
A15: 905015C | B15: 906015C | C15: Int II Computer Scientist/Systems Analyst | F15: 541614 | G15: Process, Physical Distribution, and Logistics Consulting Services
A16: 905016C | B16: 906016C | C16: Senior I Computer Scientist/Systems Analyst | F16: 541618 | G16: Other Management Consulting Services
A17: 905017C | B17: 906017C | C17: Senior Cert Computer Scientist/Systems Analyst | F17: 561110 | G17: Office Administrative Services
... A19: 905019C | B19: 906019C | C19: Senior PhD Computer Scientist/Systems Analyst | F19: 561611 | G19: Investigation Services
A20: 905020C | B20: 906020C | C20: Assoc IT Analyst
A21: 905021C | B21: 906021C | C21: Int I IT Analyst
A22: 905022C | B22: 906022C | C22: Int II IT Analyst | F22: 541330 | G22: Engineering Services
A23: 905023C | B23: 906023C | C23: Senior I IT Analyst
A24: 905024C | B24: 906024C | C24: Senior Cert IT Analyst | F24: CSS | G24: Computer Systems Support
A25: 905025C | B25: 906025C | C25: Senior II IT Analyst | F25: CSD | G25: Computer Systems Development
A26: 905026C | B26: 906026C | C26: Senior PhD IT Analyst | F26: 541430 | G26: Graphic Design Services
A27: 905027C | B27: 906027C | C27: Assoc System Security/Information Assurance Analyst | F27: 541511 | G27: Custom Computer Programming Services
A28: 905028C | B28: 906028C | C28: Int I System Security/Information Assurance Analyst | F28: 541512 | G28: Computer Systems Design Services
A29: 905029C | B29: 906029C | C29: Int II System Security/Information Assurance Analyst | F29: 518210 | G29: Data Processing, Hosting, and Related Services
A30: 905030C | B30: 906030C | C30: Senior I System Security/Information Assurance Analyst | F30: 519190 | G30: All Other Information Services
A31: 905031C | B31: 906031C | C31: Senior Cert System Security/Information Assurance Analyst | F31: 541513 | G31: Computer Facilities Management Services
A32: 905032C | B32: 906032C | C32: Senior II System Security/Information Assurance Analyst | F32: 541519 | G32: Other Computer Related Services
A33: 905033C | B33: 906033C | C33: Senior PhD System Security/Information Assurance Analyst
A34: 905034C | B34: 906034C | C34: Assoc Technical Writer | F34: 541330 | G34: Engineering Services | I34: ES
A35: 905035C | B35: 906035C | C35: Int I Technical Writer
A36: 905036C | B36: 906036C | C36: Int II Technical Writer
A37: 905037C | B37: 906037C | C37: Senior I Technical Writer | F37: =IF(Instructions!D11="Select FA from the drop down list",1,0) -> 0
A38: 905038C | B38: 906038C | C38: Senior Cert Technical Writer | F38: =IF(Instructions!D12="Please select a valid NAICS Code for the FA selected",1,0) -> 1
A39: 905039C | B39: 906039C | C39: Senior II Technical Writer | F39: =IF('CLINs & Ceiling Rates'!C5="Select FA in the Instructions tab to display CLINs",1,0) -> 0
A40: 905040C | B40: 906040C | C40: Senior PhD Technical Writer
A41: 905041C | B41: 906041C | C41: Assoc Writer/Editor
...

Sheet CLINs & Ceiling Rates
B1: Auto+Hide
B2: eFAST Procurement Action 26-017-C8
B4: PROPOSED CONTRACT CLINs
C5: =IF(D5="","Select FA in the Instructions tab to display CLINs","FUNCTIONAL AREA (as selected in the Instructions tab):") -> FUNCTIONAL AREA (as selected in the Instructions tab): | D5: =IF(Instructions!C11=0,"Please select FA in the Instructions Tab",Instructions!C11) -> BAM | I5: Annual Escalation | K5: Annual Escalation | M5: Annual Escalation | O5: Annual Escalation
D6: FY2026 | E6: For All Period of Performance | G6: =CONCATENATE("Base ",$C224) -> Base Period | I6: =CONCATENATE("Option ",$C224," 1") -> Option Period 1 | K6: =CONCATENATE("Option ",$C224," 2") -> Option Period 2 | M6: =CONCATENATE("Option ",$C224," 3") -> Option Period 3 | O6: =CONCATENATE("Option ",$C224," 4") -> Option Period 4
B7: ROLE | C7: eFAST LABOR CATEGORY | D7: WORK LOCATION | E7: PRIME OR SUB | F7: SUBCONTRACTOR NAME | G7: eFAST CLIN | H7: =CONCATENATE("J-4 ",VLOOKUP(SelectedFY,FiscalYearProgramYear,3,FALSE),"/"," ","PY",VLOOKUP(SelectedFY,FiscalYearProgramYear,2,FALSE)," Ceiling Rate") -> J-4 FY26/ PY17 Ceiling Rate | I7: eFAST CLIN | J7: Celing Labor Rate | K7: eFAST CLIN | L7: Celing Labor Rate | M7: eFAST CLIN | N7: Celing Labor Rate | O7: eFAST CLIN | P7: Celing Labor Rate
A8: =IF(B8="","Hide","") | B8: Administrative Project Manager | C8: Administrative Project Manager | D8: Contractor site - C | G8: =IFERROR(CONCATENATE(VLOOKUP($D$6,FiscalYearProgramYear,2,FALSE),0,VLOOKUP('CLINs & Ceiling Rates'!$D$5,NAICS!$N$11:$P$18,3,FALSE),VLOOKUP('CLINs & Ceiling Rates'!C8,NAICS!$V$1:$W$153,2,FALSE),VLOOKUP('CLINs & Ceiling Rates'!D8,NAICS!$O$6:$P$7,2,FALSE)),"") -> 1702003C | I8: =IFERROR(CONCATENATE((LEFT(G8,2)+1),RIGHT(G8,6)),"") -> 1802003C | J8: =ROUND(H8*(1+J$5),2) -> 0 | K8: =IFERROR(CONCATENATE((LEFT(I8,2)+1),RIGHT(I8,6)),"") -> 1902003C | L8: =ROUND(J8*(1+L$5),2) -> 0 | M8: =IFERROR(CONCATENATE((LEFT(K8,2)+1),RIGHT(K8,6)),"") -> 2002003C | N8: =ROUND(L8*(1+N$5),2) -> 0 | O8: =IFERROR(CONCATENATE((LEFT(M8,2)+1),RIGHT(M8,6)),"") -> 2102003C | P8: =ROUND(N8*(1+P$5),2) -> 0
A9: =IF(B9="","Hide","") | B9: Senior II Business/Financial/Management Analyst | C9: Senior II Business/Financial/Management Analyst | D9: Contractor site - C | G9: =IFERROR(CONCATENATE(VLOOKUP($D$6,FiscalYearProgramYear,2,FALSE),0,VLOOKUP('CLINs & Ceiling Rates'!$D$5,NAICS!$N$11:$P$18,3,FALSE),VLOOKUP('CLINs & Ceiling Rates'!C9,NAICS!$V$1:$W$153,2,FALSE),VLOOKUP('CLINs & Ceiling Rates'!D9,NAICS!$O$6:$P$7,2,FALSE)),"") -> 1702060C | I9: =IFERROR(CONCATENATE((LEFT(G9,2)+1),RIGHT(G9,6)),"") -> 1802060C | J9: =ROUND(H9*(1+J$5),2) -> 0 | K9: =IFERROR(CONCATENATE((LEFT(I9,2)+1),RIGHT(I9,6)),"") -> 1902060C | L9: =ROUND(J9*(1+L$5),2) -> 0 | M9: =IFERROR(CONCATENATE((LEFT(K9,2)+1),RIGHT(K9,6)),"") -> 2002060C | N9: =ROUND(L9*(1+N$5),2) -> 0 | O9: =IFERROR(CONCATENATE((LEFT(M9,2)+1),RIGHT(M9,6)),"") -> 2102060C | P9: =ROUND(N9*(1+P$5),2) -> 0
A10: =IF(B10="","Hide","") | B10: Senior II Business/Financial/Management Analyst | C10: Senior II Business/Financial/Management Analyst | D10: Contractor site - C | G10: =IFERROR(CONCATENATE(VLOOKUP($D$6,FiscalYearProgramYear,2,FALSE),0,VLOOKUP('CLINs & Ceiling Rates'!$D$5,NAICS!$N$11:$P$18,3,FALSE),VLOOKUP('CLINs & Ceiling Rates'!C10,NAICS!$V$1:$W$153,2,FALSE),VLOOKUP('CLINs & Ceiling Rates'!D10,NAICS!$O$6:$P$7,2,FALSE)),"") -> 1702060C | I10: =IFERROR(CONCATENATE((LEFT(G10,2)+1),RIGHT(G10,6)),"") -> 1802060C | J10: =ROUND(H10*(1+J$5),2) -> 0 | K10: =IFERROR(CONCATENATE((LEFT(I10,2)+1),RIGHT(I10,6)),"") -> 1902060C | L10: =ROUND(J10*(1+L$5),2) -> 0 | M10: =IFERROR(CONCATENATE((LEFT(K10,2)+1),RIGHT(K10,6)),"") -> 2002060C | N10: =ROUND(L10*(1+N$5),2) -> 0 | O10: =IFERROR(CONCATENATE((LEFT(M10,2)+1),RIGHT(M10,6)),"") -> 2102060C | P10: =ROUND(N10*(1+P$5),2) -> 0
A11: =IF(B11="","Hide","") | B11: Senior II Business/Financial/Management Analyst | C11: Senior II Business/Financial/Management Analyst | D11: Contractor site - C | G11: =IFERROR(CONCATENATE(VLOOKUP($D$6,FiscalYearProgramYear,2,FALSE),0,VLOOKUP('CLINs & Ceiling Rates'!$D$5,NAICS!$N$11:$P$18,3,FALSE),VLOOKUP('CLINs & Ceiling Rates'!C11,NAICS!$V$1:$W$153,2,FALSE),VLOOKUP('CLINs & Ceiling Rates'!D11,NAICS!$O$6:$P$7,2,FALSE)),"") -> 1702060C | I11: =IFERROR(CONCATENATE((LEFT(G11,2)+1),RIGHT(G11,6)),"") -> 1802060C | J11: =ROUND(H11*(1+J$5),2) -> 0 | K11: =IFERROR(CONCATENATE((LEFT(I11,2)+1),RIGHT(I11,6)),"") -> 1902060C | L11: =ROUND(J11*(1+L$5),2) -> 0 | M11: =IFERROR(CONCATENATE((LEFT(K11,2)+1),RIGHT(K11,6)),"") -> 2002060C | N11: =ROUND(L11*(1+N$5),2) -> 0 | O11: =IFERROR(CONCATENATE((LEFT(M11,2)+1),RIGHT(M11,6)),"") -> 2102060C | P11: =ROUND(N11*(1+P$5),2) -> 0
A12: =IF(B12="","Hide","") | B12: Senior I Business/Financial/Management Analyst | C12: Senior I Business/Financial/Management Analyst | D12: Contractor site - C | G12: =IFERROR(CONCATENATE(VLOOKUP($D$6,FiscalYearProgramYear,2,FALSE),0,VLOOKUP('CLINs & Ceiling Rates'!$D$5,NAICS!$N$11:$P$18,3,FALSE),VLOOKUP('CLINs & Ceiling Rates'!C12,NAICS!$V$1:$W$153,2,FALSE),VLOOKUP('CLINs & Ceiling Rates'!D12,NAICS!$O$6:$P$7,2,FALSE)),"") -> 1702058C | I12: =IFERROR(CONCATENATE((LEFT(G12,2)+1),RIGHT(G12,6)),"") -> 1802058C | J12: =ROUND(H12*(1+J$5),2) -> 0 | K12: =IFERROR(CONCATENATE((LEFT(I12,2)+1),RIGHT(I12,6)),"") -> 1902058C | L12: =ROUND(J12*(1+L$5),2) -> 0 | M12: =IFERROR(CONCATENATE((LEFT(K12,2)+1),RIGHT(K12,6)),"") -> 2002058C | N12: =ROUND(L12*(1+N$5),2) -> 0 | O12: =IFERROR(CONCATENATE((LEFT(M12,2)+1),RIGHT(M12,6)),"") -> 2102058C | P12: =ROUND(N12*(1+P$5),2) -> 0
A13: =IF(B13="","Hide","") | B13: Senior I Business/Financial/Management Analyst | C13: Senior I Business/Financial/Management Analyst | D13: Contractor site - C | G13: =IFERROR(CONCATENATE(VLOOKUP($D$6,FiscalYearProgramYear,2,FALSE),0,VLOOKUP('CLINs & Ceiling Rates'!$D$5,NAICS!$N$11:$P$18,3,FALSE),VLOOKUP('CLINs & Ceiling Rates'!C13,NAICS!$V$1:$W$153,2,FALSE),VLOOKUP('CLINs & Ceiling Rates'!D13,NAICS!$O$6:$P$7,2,FALSE)),"") -> 1702058C | I13: =IFERROR(CONCATENATE((LEFT(G13,2)+1),RIGHT(G13,6)),"") -> 1802058C | J13: =ROUND(H13*(1+J$5),2) -> 0 | K13: =IFERROR(CONCATENATE((LEFT(I13,2)+1),RIGHT(I13,6)),"") -> 1902058C | L13: =ROUND(J13*(1+L$5),2) -> 0 | M13: =IFERROR(CONCATENATE((LEFT(K13,2)+1),RIGHT(K13,6)),"") -> 2002058C | N13: =ROUND(L13*(1+N$5),2) -> 0 | O13: =IFERROR(CONCATENATE((LEFT(M13,2)+1),RIGHT(M13,6)),"") -> 2102058C | P13: =ROUND(N13*(1+P$5),2) -> 0
A14: =IF(B14="","Hide","") | B14: Senior I Business/Financial/Management Analyst | C14: Senior I Business/Financial/Management Analyst | D14: Contractor site - C | G14: =IFERROR(CONCATENATE(VLOOKUP($D$6,FiscalYearProgramYear,2,FALSE),0,VLOOKUP('CLINs & Ceiling Rates'!$D$5,NAICS!$N$11:$P$18,3,FALSE),VLOOKUP('CLINs & Ceiling Rates'!C14,NAICS!$V$1:$W$153,2,FALSE),VLOOKUP('CLINs & Ceiling Rates'!D14,NAICS!$O$6:$P$7,2,FALSE)),"") -> 1702058C | I14: =IFERROR(CONCATENATE((LEFT(G14,2)+1),RIGHT(G14,6)),"") -> 1802058C | J14: =ROUND(H14*(1+J$5),2) -> 0 | K14: =IFERROR(CONCATENATE((LEFT(I14,2)+1),RIGHT(I14,6)),"") -> 1902058C | L14: =ROUND(J14*(1+L$5),2) -> 0 | M14: =IFERROR(CONCATENATE((LEFT(K14,2)+1),RIGHT(K14,6)),"") -> 2002058C | N14: =ROUND(L14*(1+N$5),2) -> 0 | O14: =IFERROR(CONCATENATE((LEFT(M14,2)+1),RIGHT(M14,6)),"") -> 2102058C | P14: =ROUND(N14*(1+P$5),2) -> 0
A15: =IF(B15="","Hide","") | B15: Senior I Business/Financial/Management Analyst | C15: Senior I Business/Financial/Management Analyst | D15: Contractor site - C | G15: =IFERROR(CONCATENATE(VLOOKUP($D$6,FiscalYearProgramYear,2,FALSE),0,VLOOKUP('CLINs & Ceiling Rates'!$D$5,NAICS!$N$11:$P$18,3,FALSE),VLOOKUP('CLINs & Ceiling Rates'!C15,NAICS!$V$1:$W$153,2,FALSE),VLOOKUP('CLINs & Ceiling Rates'!D15,NAICS!$O$6:$P$7,2,FALSE)),"") -> 1702058C | I15: =IFERROR(CONCATENATE((LEFT(G15,2)+1),RIGHT(G15,6)),"") -> 1802058C | J15: =ROUND(H15*(1+J$5),2) -> 0 | K15: =IFERROR(CONCATENATE((LEFT(I15,2)+1),RIGHT(I15,6)),"") -> 1902058C | L15: =ROUND(J15*(1+L$5),2) -> 0 | M15: =IFERROR(CONCATENATE((LEFT(K15,2)+1),RIGHT(K15,6)),"") -> 2002058C | N15: =ROUND(L15*(1+N$5),2) -> 0 | O15: =IFERROR(CONCATENATE((LEFT(M15,2)+1),RIGHT(M15,6)),"") -> 2102058C | P15: =ROUND(N15*(1+P$5),2) -> 0
A16: =IF(B16="","Hide","") | B16: Int II Business/Financial/Management Analyst | C16: Int II Business/Financial/Management Analyst | D16: Contractor site - C | G16: =IFERROR(CONCATENATE(VLOOKUP($D$6,FiscalYearProgramYear,2,FALSE),0,VLOOKUP('CLINs & Ceiling Rates'!$D$5,NAICS!$N$11:$P$18,3,FALSE),VLOOKUP('CLINs & Ceiling Rates'!C16,NAICS!$V$1:$W$153,2,FALSE),VLOOKUP('CLINs & Ceiling Rates'!D16,NAICS!$O$6:$P$7,2,FALSE)),"") -> 1702057C | I16: =IFERROR(CONCATENATE((LEFT(G16,2)+1),RIGHT(G16,6)),"") -> 1802057C | J16: =ROUND(H16*(1+J$5),2) -> 0 | K16: =IFERROR(CONCATENATE((LEFT(I16,2)+1),RIGHT(I16,6)),"") -> 1902057C | L16: =ROUND(J16*(1+L$5),2) -> 0 | M16: =IFERROR(CONCATENATE((LEFT(K16,2)+1),RIGHT(K16,6)),"") -> 2002057C | N16: =ROUND(L16*(1+N$5),2) -> 0 | O16: =IFERROR(CONCATENATE((LEFT(M16,2)+1),RIGHT(M16,6)),"") -> 2102057C | P16: =ROUND(N16*(1+P$5),2) -> 0
A17: =IF(B17="","Hide","") | B17: Int II Business/Financial/Management Analyst | C17: Int II Business/Financial/Management Analyst | D17: Contractor site - C | G17: =IFERROR(CONCATENATE(VLOOKUP($D$6,FiscalYearProgramYear,2,FALSE),0,VLOOKUP('CLINs & Ceiling Rates'!$D$5,NAICS!$N$11:$P$18,3,FALSE),VLOOKUP('CLINs & Ceiling Rates'!C17,NAICS!$V$1:$W$153,2,FALSE),VLOOKUP('CLINs & Ceiling Rates'!D17,NAICS!$O$6:$P$7,2,FALSE)),"") -> 1702057C | I17: =IFERROR(CONCATENATE((LEFT(G17,2)+1),RIGHT(G17,6)),"") -> 1802057C | J17: =ROUND(H17*(1+J$5),2) -> 0 | K17: =IFERROR(CONCATENATE((LEFT(I17,2)+1),RIGHT(I17,6)),"") -> 1902057C | L17: =ROUND(J17*(1+L$5),2) -> 0 | M17: =IFERROR(CONCATENATE((LEFT(K17,2)+1),RIGHT(K17,6)),"") -> 2002057C | N17: =ROUND(L17*(1+N$5),2) -> 0 | O17: =IFERROR(CONCATENATE((LEFT(M17,2)+1),RIGHT(M17,6)),"") -> 2102057C | P17: =ROUND(N17*(1+P$5),2) -> 0
A18: =IF(B18="","Hide","") | B18: Int II Business/Financial/Management Analyst | C18: Int II Business/Financial/Management Analyst | D18: Contractor site - C | G18: =IFERROR(CONCATENATE(VLOOKUP($D$6,FiscalYearProgramYear,2,FALSE),0,VLOOKUP('CLINs & Ceiling Rates'!$D$5,NAICS!$N$11:$P$18,3,FALSE),VLOOKUP('CLINs & Ceiling Rates'!C18,NAICS!$V$1:$W$153,2,FALSE),VLOOKUP('CLINs & Ceiling Rates'!D18,NAICS!$O$6:$P$7,2,FALSE)),"") -> 1702057C | I18: =IFERROR(CONCATENATE((LEFT(G18,2)+1),RIGHT(G18,6)),"") -> 1802057C | J18: =ROUND(H18*(1+J$5),2) -> 0 | K18: =IFERROR(CONCATENATE((LEFT(I18,2)+1),RIGHT(I18,6)),"") -> 1902057C | L18: =ROUND(J18*(1+L$5),2) -> 0 | M18: =IFERROR(CONCATENATE((LEFT(K18,2)+1),RIGHT(K18,6)),"") -> 2002057C | N18: =ROUND(L18*(1+N$5),2) -> 0 | O18: =IFERROR(CONCATENATE((LEFT(M18,2)+1),RIGHT(M18,6)),"") -> 2102057C | P18: =ROUND(N18*(1+P$5),2) -> 0
A19: =IF(B19="","Hide","") | B19: Int II Business/Financial/Management Analyst | C19: Int II Business/Financial/Management Analyst | D19: Contractor site - C | G19: =IFERROR(CONCATENATE(VLOOKUP($D$6,FiscalYearProgramYear,2,FALSE),0,VLOOKUP('CLINs & Ceiling Rates'!$D$5,NAICS!$N$11:$P$18,3,FALSE),VLOOKUP('CLINs & Ceiling Rates'!C19,NAICS!$V$1:$W$153,2,FALSE),VLOOKUP('CLINs & Ceiling Rates'!D19,NAICS!$O$6:$P$7,2,FALSE)),"") -> 1702057C | I19: =IFERROR(CONCATENATE((LEFT(G19,2)+1),RIGHT(G19,6)),"") -> 1802057C | J19: =ROUND(H19*(1+J$5),2) -> 0 | K19: =IFERROR(CONCATENATE((LEFT(I19,2)+1),RIGHT(I19,6)),"") -> 1902057C | L19: =ROUND(J19*(1+L$5),2) -> 0 | M19: =IFERROR(CONCATENATE((LEFT(K19,2)+1),RIGHT(K19,6)),"") -> 2002057C | N19: =ROUND(L19*(1+N$5),2) -> 0 | O19: =IFERROR(CONCATENATE((LEFT(M19,2)+1),RIGHT(M19,6)),"") -> 2102057C | P19: =ROUND(N19*(1+P$5),2) -> 0
A20: =IF(B20="","Hide","") -> Hide | G20: =IFERROR(CONCATENATE(VLOOKUP($D$6,FiscalYearProgramYear,2,FALSE),0,VLOOKUP('CLINs & Ceiling Rates'!$D$5,NAICS!$N$11:$P$18,3,FALSE),VLOOKUP('CLINs & Ceiling Rates'!C20,NAICS!$V$1:$W$153,2,FALSE),VLOOKUP('CLINs & Ceiling Rates'!D20,NAICS!$O$6:$P$7,2,FALSE)),"") | I20: =IFERROR(CONCATENATE((LEFT(G20,2)+1),RIGHT(G20,6)),"") | J20: =ROUND(H20*(1+J$5),2) -> 0 | K20: =IFERROR(CONCATENATE((LEFT(I20,2)+1),RIGHT(I20,6)),"") | L20: =ROUND(J20*(1+L$5),2) -> 0 | M20: =IFERROR(CONCATENATE((LEFT(K20,2)+1),RIGHT(K20,6)),"") | N20: =ROUND(L20*(1+N$5),2) -> 0 | O20: =IFERROR(CONCATENATE((LEFT(M20,2)+1),RIGHT(M20,6)),"") | P20: =ROUND(N20*(1+P$5),2) -> 0
A21: =IF(B21="","Hide","") -> Hide | G21: =IFERROR(CONCATENATE(VLOOKUP($D$6,FiscalYearProgramYear,2,FALSE),0,VLOOKUP('CLINs & Ceiling Rates'!$D$5,NAICS!$N$11:$P$18,3,FALSE),VLOOKUP('CLINs & Ceiling Rates'!C21,NAICS!$V$1:$W$153,2,FALSE),VLOOKUP('CLINs & Ceiling Rates'!D21,NAICS!$O$6:$P$7,2,FALSE)),"") | I21: =IFERROR(CONCATENATE((LEFT(G21,2)+1),RIGHT(G21,6)),"") | J21: =ROUND(H21*(1+J$5),2) -> 0 | K21: =IFERROR(CONCATENATE((LEFT(I21,2)+1),RIGHT(I21,6)),"") | L21: =ROUND(J21*(1+L$5),2) -> 0 | M21: =IFERROR(CONCATENATE((LEFT(K21,2)+1),RIGHT(K21,6)),"") | N21: =ROUND(L21*(1+N$5),2) -> 0 | O21: =IFERROR(CONCATENATE((LEFT(M21,2)+1),RIGHT(M21,6)),"") | P21: =ROUND(N21*(1+P$5),2) -> 0
A22: =IF(B22="","Hide","") -> Hide | G22: =IFERROR(CONCATENATE(VLOOKUP($D$6,FiscalYearProgramYear,2,FALSE),0,VLOOKUP('CLINs & Ceiling Rates'!$D$5,NAICS!$N$11:$P$18,3,FALSE),VLOOKUP('CLINs & Ceiling Rates'!C22,NAICS!$V$1:$W$153,2,FALSE),VLOOKUP('CLINs & Ceiling Rates'!D22,NAICS!$O$6:$P$7,2,FALSE)),"") | I22: =IFERROR(CONCATENATE((LEFT(G22,2)+1),RIGHT(G22,6)),"") | J22: =ROUND(H22*(1+J$5),2) -> 0 | K22: =IFERROR(CONCATENATE((LEFT(I22,2)+1),RIGHT(I22,6)),"") | L22: =ROUND(J22*(1+L$5),2) -> 0 | M22: =IFERROR(CONCATENATE((LEFT(K22,2)+1),RIGHT(K22,6)),"") | N22: =ROUND(L22*(1+N$5),2) -> 0 | O22: =IFERROR(CONCATENATE((LEFT(M22,2)+1),RIGHT(M22,6)),"") | P22: =ROUND(N22*(1+P$5),2) -> 0
A23: =IF(B23="","Hide","") -> Hide | G23: =IFERROR(CONCATENATE(VLOOKUP($D$6,FiscalYearProgramYear,2,FALSE),0,VLOOKUP('CLINs & Ceiling Rates'!$D$5,NAICS!$N$11:$P$18,3,FALSE),VLOOKUP('CLINs & Ceiling Rates'!C23,NAICS!$V$1:$W$153,2,FALSE),VLOOKUP('CLINs & Ceiling Rates'!D23,NAICS!$O$6:$P$7,2,FALSE)),"") | I23: =IFERROR(CONCATENATE((LEFT(G23,2)+1),RIGHT(G23,6)),"") | J23: =ROUND(H23*(1+J$5),2) -> 0 | K23: =IFERROR(CONCATENATE((LEFT(I23,2)+1),RIGHT(I23,6)),"") | L23: =ROUND(J23*(1+L$5),2) -> 0 | M23: =IFERROR(CONCATENATE((LEFT(K23,2)+1),RIGHT(K23,6)),"") | N23: =ROUND(L23*(1+N$5),2) -> 0 | O23: =IFERROR(CONCATENATE((LEFT(M23,2)+1),RIGHT(M23,6)),"") | P23: =ROUND(N23*(1+P$5),2) -> 0
A24: =IF(B24="","Hide","") -> Hide | G24: =IFERROR(CONCATENATE(VLOOKUP($D$6,FiscalYearProgramYear,2,FALSE),0,VLOOKUP('CLINs & Ceiling Rates'!$D$5,NAICS!$N$11:$P$18,3,FALSE),VLOOKUP('CLINs & Ceiling Rates'!C24,NAICS!$V$1:$W$153,2,FALSE),VLOOKUP('CLINs & Ceiling Rates'!D24,NAICS!$O$6:$P$7,2,FALSE)),"") | I24: =IFERROR(CONCATENATE((LEFT(G24,2)+1),RIGHT(G24,6)),"") | J24: =ROUND(H24*(1+J$5),2) -> 0 | K24: =IFERROR(CONCATENATE((LEFT(I24,2)+1),RIGHT(I24,6)),"") | L24: =ROUND(J24*(1+L$5),2) -> 0 | M24: =IFERROR(CONCATENATE((LEFT(K24,2)+1),RIGHT(K24,6)),"") | N24: =ROUND(L24*(1+N$5),2) -> 0 | O24: =IFERROR(CONCATENATE((LEFT(M24,2)+1),RIGHT(M24,6)),"") | P24: =ROUND(N24*(1+P$5),2) -> 0
A25: =IF(B25="","Hide","") -> Hide | G25: =IFERROR(CONCATENATE(VLOOKUP($D$6,FiscalYearProgramYear,2,FALSE),0,VLOOKUP('CLINs & Ceiling Rates'!$D$5,NAICS!$N$11:$P$18,3,FALSE),VLOOKUP('CLINs & Ceiling Rates'!C25,NAICS!$V$1:$W$153,2,FALSE),VLOOKUP('CLINs & Ceiling Rates'!D25,NAICS!$O$6:$P$7,2,FALSE)),"") | I25: =IFERROR(CONCATENATE((LEFT(G25,2)+1),RIGHT(G25,6)),"") | J25: =ROUND(H25*(1+J$5),2) -> 0 | K25: =IFERROR(CONCATENATE((LEFT(I25,2)+1),RIGHT(I25,6)),"") | L25: =ROUND(J25*(1+L$5),2) -> 0 | M25: =IFERROR(CONCATENATE((LEFT(K25,2)+1),RIGHT(K25,6)),"") | N25: =ROUND(L25*(1+N$5),2) -> 0 | O25: =IFERROR(CONCATENATE((LEFT(M25,2)+1),RIGHT(M25,6)),"") | P25: =ROUND(N25*(1+P$5),2) -> 0
A26: =IF(B26="","Hide","") -> Hide | G26: =IFERROR(CONCATENATE(VLOOKUP($D$6,FiscalYearProgramYear,2,FALSE),0,VLOOKUP('CLINs & Ceiling Rates'!$D$5,NAICS!$N$11:$P$18,3,FALSE),VLOOKUP('CLINs & Ceiling Rates'!C26,NAICS!$V$1:$W$153,2,FALSE),VLOOKUP('CLINs & Ceiling Rates'!D26,NAICS!$O$6:$P$7,2,FALSE)),"") | I26: =IFERROR(CONCATENATE((LEFT(G26,2)+1),RIGHT(G26,6)),"") | J26: =ROUND(H26*(1+J$5),2) -> 0 | K26: =IFERROR(CONCATENATE((LEFT(I26,2)+1),RIGHT(I26,6)),"") | L26: =ROUND(J26*(1+L$5),2) -> 0 | M26: =IFERROR(CONCATENATE((LEFT(K26,2)+1),RIGHT(K26,6)),"") | N26: =ROUND(L26*(1+N$5),2) -> 0 | O26: =IFERROR(CONCATENATE((LEFT(M26,2)+1),RIGHT(M26,6)),"") | P26: =ROUND(N26*(1+P$5),2) -> 0
A27: =IF(B27="","Hide","") -> Hide | G27: =IFERROR(CONCATENATE(VLOOKUP($D$6,FiscalYearProgramYear,2,FALSE),0,VLOOKUP('CLINs & Ceiling Rates'!$D$5,NAICS!$N$11:$P$18,3,FALSE),VLOOKUP('CLINs & Ceiling Rates'!C27,NAICS!$V$1:$W$153,2,FALSE),VLOOKUP('CLINs & Ceiling Rates'!D27,NAICS!$O$6:$P$7,2,FALSE)),"") | I27: =IFERROR(CONCATENATE((LEFT(G27,2)+1),RIGHT(G27,6)),"") | J27: =ROUND(H27*(1+J$5),2) -> 0 | K27: =IFERROR(CONCATENATE((LEFT(I27,2)+1),RIGHT(I27,6)),"") | L27: =ROUND(J27*(1+L$5),2) -> 0 | M27: =IFERROR(CONCATENATE((LEFT(K27,2)+1),RIGHT(K27,6)),"") | N27: =ROUND(L27*(1+N$5),2) -> 0 | O27: =IFERROR(CONCATENATE((LEFT(M27,2)+1),RIGHT(M27,6)),"") | P27: =ROUND(N27*(1+P$5),2) -> 0
A28: =IF(B28="","Hide","") -> Hide | G28: =IFERROR(CONCATENATE(VLOOKUP($D$6,FiscalYearProgramYear,2,FALSE),0,VLOOKUP('CLINs & Ceiling Rates'!$D$5,NAICS!$N$11:$P$18,3,FALSE),VLOOKUP('CLINs & Ceiling Rates'!C28,NAICS!$V$1:$W$153,2,FALSE),VLOOKUP('CLINs & Ceiling Rates'!D28,NAICS!$O$6:$P$7,2,FALSE)),"") | I28: =IFERROR(CONCATENATE((LEFT(G28,2)+1),RIGHT(G28,6)),"") | J28: =ROUND(H28*(1+J$5),2) -> 0 | K28: =IFERROR(CONCATENATE((LEFT(I28,2)+1),RIGHT(I28,6)),"") | L28: =ROUND(J28*(1+L$5),2) -> 0 | M28: =IFERROR(CONCATENATE((LEFT(K28,2)+1),RIGHT(K28,6)),"") | N28: =ROUND(L28*(1+N$5),2) -> 0 | O28: =IFERROR(CONCATENATE((LEFT(M28,2)+1),RIGHT(M28,6)),"") | P28: =ROUND(N28*(1+P$5),2) -> 0
A29: =IF(B29="","Hide","") -> Hide | G29: =IFERROR(CONCATENATE(VLOOKUP($D$6,FiscalYearProgramYear,2,FALSE),0,VLOOKUP('CLINs & Ceiling Rates'!$D$5,NAICS!$N$11:$P$18,3,FALSE),VLOOKUP('CLINs & Ceiling Rates'!C29,NAICS!$V$1:$W$153,2,FALSE),VLOOKUP('CLINs & Ceiling Rates'!D29,NAICS!$O$6:$P$7,2,FALSE)),"") | I29: =IFERROR(CONCATENATE((LEFT(G29,2)+1),RIGHT(G29,6)),"") | J29: =ROUND(H29*(1+J$5),2) -> 0 | K29: =IFERROR(CONCATENATE((LEFT(I29,2)+1),RIGHT(I29,6)),"") | L29: =ROUND(J29*(1+L$5),2) -> 0 | M29: =IFERROR(CONCATENATE((LEFT(K29,2)+1),RIGHT(K29,6)),"") | N29: =ROUND(L29*(1+N$5),2) -> 0 | O29: =IFERROR(CONCATENATE((LEFT(M29,2)+1),RIGHT(M29,6)),"") | P29: =ROUND(N29*(1+P$5),2) -> 0
A30: =IF(B30="","Hide","") -> Hide | G30: =IFERROR(CONCATENATE(VLOOKUP($D$6,FiscalYearProgramYear,2,FALSE),0,VLOOKUP('CLINs & Ceiling Rates'!$D$5,NAICS!$N$11:$P$18,3,FALSE),VLOOKUP('CLINs & Ceiling Rates'!C30,NAICS!$V$1:$W$153,2,FALSE),VLOOKUP('CLINs & Ceiling Rates'!D30,NAICS!$O$6:$P$7,2,FALSE)),"") | I30: =IFERROR(CONCATENATE((LEFT(G30,2)+1),RIGHT(G30,6)),"") | J30: =ROUND(H30*(1+J$5),2) -> 0 | K30: =IFERROR(CONCATENATE((LEFT(I30,2)+1),RIGHT(I30,6)),"") | L30: =ROUND(J30*(1+L$5),2) -> 0 | M30: =IFERROR(CONCATENATE((LEFT(K30,2)+1),RIGHT(K30,6)),"") | N30: =ROUND(L30*(1+N$5),2) -> 0 | O30: =IFERROR(CONCATENATE((LEFT(M30,2)+1),RIGHT(M30,6)),"") | P30: =ROUND(N30*(1+P$5),2) -> 0
A31: =IF(B31="","Hide","") -> Hide | G31: =IFERROR(CONCATENATE(VLOOKUP($D$6,FiscalYearProgramYear,2,FALSE),0,VLOOKUP('CLINs & Ceiling Rates'!$D$5,NAICS!$N$11:$P$18,3,FALSE),VLOOKUP('CLINs & Ceiling Rates'!C31,NAICS!$V$1:$W$153,2,FALSE),VLOOKUP('CLINs & Ceiling Rates'!D31,NAICS!$O$6:$P$7,2,FALSE)),"") | I31: =IFERROR(CONCATENATE((LEFT(G31,2)+1),RIGHT(G31,6)),"") | J31: =ROUND(H31*(1+J$5),2) -> 0 | K31: =IFERROR(CONCATENATE((LEFT(I31,2)+1),RIGHT(I31,6)),"") | L31: =ROUND(J31*(1+L$5),2) -> 0 | M31: =IFERROR(CONCATENATE((LEFT(K31,2)+1),RIGHT(K31,6)),"") | N31: =ROUND(L31*(1+N$5),2) -> 0 | O31: =IFERROR(CONCATENATE((LEFT(M31,2)+1),RIGHT(M31,6)),"") | P31: =ROUND(N31*(1+P$5),2) -> 0
... A217: =IF(B217="","Hide","") -> Hide | G217: =IFERROR(CONCATENATE(VLOOKUP($D$6,FiscalYearProgramYear,2,FALSE),0,VLOOKUP('CLINs & Ceiling Rates'!$D$5,NAICS!$N$11:$P$18,3,FALSE),VLOOKUP('CLINs & Ceiling Rates'!C217,NAICS!$V$1:$W$153,2,FALSE),VLOOKUP('CLINs & Ceiling Rates'!D217,NAICS!$O$6:$P$7,2,FALSE)),"") | I217: =IFERROR(CONCATENATE((LEFT(G217,2)+1),RIGHT(G217,6)),"") | J217: =ROUND(H217*(1+J$5),2) -> 0 | K217: =IFERROR(CONCATENATE((LEFT(I217,2)+1),RIGHT(I217,6)),"") | L217: =ROUND(J217*(1+L$5),2) -> 0 | M217: =IFERROR(CONCATENATE((LEFT(K217,2)+1),RIGHT(K217,6)),"") | N217: =ROUND(L217*(1+N$5),2) -> 0 | O217: =IFERROR(CONCATENATE((LEFT(M217,2)+1),RIGHT(M217,6)),"") | P217: =ROUND(N217*(1+P$5),2) -> 0
A222: =IF(B222="","Hide","") | B222: Hide This Section Once Completed | G222: Please hide ROW 161-195. Do not hide column.
A223: =IF(C223="","Hide","") | B223: Maximumn Number of Option Period | C223: 4
B224: Base & Option Year/Period | C224: Period
A225: =IF(C225="","Hide","") | B225: Contract Type | C225: Time and Materials (T&M)
A226: =IF(C226="","Hide","") | C226: Hide This Section Once Completed
A227: =IF(C227="","Hide","") | C227: ODCs | D227: =CONCATENATE("Base ",C224) -> Base Period | E227: =CONCATENATE("Option ",C224," 1") -> Option Period 1 | F227: =CONCATENATE("Option ",$C224," 2") -> Option Period 2 | G227: =CONCATENATE("Option ",$C224," 3") -> Option Period 3 | H227: =CONCATENATE("Option ",$C224," 4") -> Option Period 4 | I227: Total Per ODC Category
A228: =IF(C228="","Hide","") | C228: Travel and Per Diem (OPS) | D228: 2000 | E228: 2000 | F228: 2000 | G228: 2000 | H228: 2000 | I228: =SUM(D228:H228) -> 10000
A229: =IF(C229="","Hide","") | C229: Travel and Per Diem (F&E) | I229: =SUM(D229:H229) -> 0
A230: =IF(C230="","Hide","") | C230: Travel and Per Diem (R,D&E) | I230: =SUM(D230:H230) -> 0
...

Sheet Labor Loading Matrix
A1: =Instructions!A1 -> eFAST Procurement Action 26-017-C8
A3: =IF('CLINs & Ceiling Rates'!C225="Time and Materials (T&M)","Proposed T&M Labor Loading Matrix", IF('CLINs & Ceiling Rates'!C225="Firm Fixed Price / Time and Materials (FFP/T&M)",CONCATENATE("Proposed T&M Labor Loading Matrix"),CONCATENATE("Proposed ",'CLINs & Ceiling Rates'!C225," Labor Loading Matrix"))) -> Proposed T&M Labor Loading Matrix | H3: =IF('CLINs & Ceiling Rates'!C225="Firm Fixed Price (FFP)", "This Tab is Not Applicable Due to 100% FFP - Hide This Tab"," ")
A4: =CONCATENATE("Totals – All ",'CLINs & Ceiling Rates'!C224,"s") -> Totals – All Periods | B4: =IF('CLINs & Ceiling Rates'!C223=0,CONCATENATE("(Base ",'CLINs & Ceiling Rates'!C224,")"),CONCATENATE("(Base ",'CLINs & Ceiling Rates'!C224," through Option ",'CLINs & Ceiling Rates'!C224," ",'CLINs & Ceiling Rates'!$C$223,"",")")) -> (Base Period through Option Period 4)
A5: ROLE | B5: eFAST LABOR CATEGORY | C5: eFAST CLIN | D5: TOTAL HOURS | E5: Total OPS Hours | F5: Total F&E Hours | G5: =G219 -> Total R&D Hours | H5: Allocation of Hours by SOW Task
H6: =IF('CLINs & Ceiling Rates'!$C237="","",CONCATENATE("Task ",'CLINs & Ceiling Rates'!C237," ",'CLINs & Ceiling Rates'!$D237)) -> Task 1 OPS | I6: =IF('CLINs & Ceiling Rates'!$C238="","",CONCATENATE("Task ",'CLINs & Ceiling Rates'!C238," ",'CLINs & Ceiling Rates'!$D238)) -> Task 1 F&E | J6: =IF('CLINs & Ceiling Rates'!$C239="","",CONCATENATE("Task ",'CLINs & Ceiling Rates'!C239," ",'CLINs & Ceiling Rates'!$D239)) -> Task 2 OPS | K6: =IF('CLINs & Ceiling Rates'!$C240="","",CONCATENATE("Task ",'CLINs & Ceiling Rates'!C240," ",'CLINs & Ceiling Rates'!$D240)) -> Task 2 F&E | L6: =IF('CLINs & Ceiling Rates'!$C241="","",CONCATENATE("Task ",'CLINs & Ceiling Rates'!$C241," ",'CLINs & Ceiling Rates'!$D241)) | M6: =IF('CLINs & Ceiling Rates'!$C242="","",CONCATENATE("Task ",'CLINs & Ceiling Rates'!$C242," ",'CLINs & Ceiling Rates'!$D242)) | N6: =IF('CLINs & Ceiling Rates'!$C243="","",CONCATENATE("Task ",'CLINs & Ceiling Rates'!$C243," ",'CLINs & Ceiling Rates'!$D243)) | O6: =IF('CLINs & Ceiling Rates'!$C244="","",CONCATENATE("Task ",'CLINs & Ceiling Rates'!$C244," ",'CLINs & Ceiling Rates'!$D244)) | P6: =IF('CLINs & Ceiling Rates'!$C245="","",CONCATENATE("Task ",'CLINs & Ceiling Rates'!$C245," ",'CLINs & Ceiling Rates'!$D245)) | Q6: =IF('CLINs & Ceiling Rates'!$C246="","",CONCATENATE("Task ",'CLINs & Ceiling Rates'!$C246," ",'CLINs & Ceiling Rates'!$D246)) | R6: =IF('CLINs & Ceiling Rates'!$C247="","",CONCATENATE("Task ",'CLINs & Ceiling Rates'!$C247," ",'CLINs & Ceiling Rates'!$D247)) | S6: =IF('CLINs & Ceiling Rates'!$C248="","",CONCATENATE("Task ",'CLINs & Ceiling Rates'!$C248," ",'CLINs & Ceiling Rates'!$D248)) | T6: =IF('CLINs & Ceiling Rates'!$C249="","",CONCATENATE("Task ",'CLINs & Ceiling Rates'!$C249," ",'CLINs & Ceiling Rates'!$D249)) | U6: =IF('CLINs & Ceiling Rates'!$C250="","",CONCATENATE("Task ",'CLINs & Ceiling Rates'!$C250," ",'CLINs & Ceiling Rates'!$D250)) | V6: =IF('CLINs & Ceiling Rates'!$C251="","",CONCATENATE("Task ",'CLINs & Ceiling Rates'!$C251," ",'CLINs & Ceiling Rates'!$D251)) | W6: =IF('CLINs & Ceiling Rates'!$C252="","",CONCATENATE("Task ",'CLINs & Ceiling Rates'!$C252," ",'CLINs & Ceiling Rates'!$D252)) | X6: =IF('CLINs & Ceiling Rates'!$C253="","",CONCATENATE("Task ",'CLINs & Ceiling Rates'!$C253," ",'CLINs & Ceiling Rates'!$D253)) | Y6: =IF('CLINs & Ceiling Rates'!$C254="","",CONCATENATE("Task ",'CLINs & Ceiling Rates'!$C254," ",'CLINs & Ceiling Rates'!$D254)) | Z6: =IF('CLINs & Ceiling Rates'!$C255="","",CONCATENATE("Task ",'CLINs & Ceiling Rates'!$C255," ",'CLINs & Ceiling Rates'!$D255)) | AA6: =IF('CLINs & Ceiling Rates'!$C256="","",CONCATENATE("Task ",'CLINs & Ceiling Rates'!$C256," ",'CLINs & Ceiling Rates'!$D256))
A7: ='CLINs & Ceiling Rates'!B8 -> Administrative Project Manager | B7: ='CLINs & Ceiling Rates'!C8 -> Administrative Project Manager | C7: =CONCATENATE("X",RIGHT('CLINs & Ceiling Rates'!G8,6)) -> X02003C | D7: =SUM(D221,D435,D649,D863,D1079) -> 2400 | E7: =SUM(E221,E435,E649,E863,E1079) -> 1800 | F7: =SUM(F221,F435,F649,F863,F1079) -> 600 | G7: =SUM(G221,G435,G649,G863,G1079) -> 0 | H7: =IF(SUM(H221,H435,H649,H863,H1079)=0,"",SUM(H221,H435,H649,H863,H1079)) -> 1800 | I7: =IF(SUM(I221,I435,I649,I863,I1079)=0,"",SUM(I221,I435,I649,I863,I1079)) -> 600 | J7: =IF(SUM(J221,J435,J649,J863,J1079)=0,"",SUM(J221,J435,J649,J863,J1079)) | K7: =IF(SUM(K221,K435,K649,K863,K1079)=0,"",SUM(K221,K435,K649,K863,K1079)) | L7: =IF(SUM(L221,L435,L649,L863,L1079)=0,"",SUM(L221,L435,L649,L863,L1079)) | M7: =IF(SUM(M221,M435,M649,M863,M1079)=0,"",SUM(M221,M435,M649,M863,M1079)) | N7: =IF(SUM(N221,N435,N649,N863,N1079)=0,"",SUM(N221,N435,N649,N863,N1079)) | O7: =IF(SUM(O221,O435,O649,O863,O1079)=0,"",SUM(O221,O435,O649,O863,O1079)) | ... AA7: =IF(SUM(AA221,AA435,AA649,AA863,AA1079)=0,"",SUM(AA221,AA435,AA649,AA863,AA1079))
A8: ='CLINs & Ceiling Rates'!B9 -> Senior II Business/Financial/Management Analyst | B8: ='CLINs & Ceiling Rates'!C9 -> Senior II Business/Financial/Management Analyst | C8: =CONCATENATE("X",RIGHT('CLINs & Ceiling Rates'!G9,6)) -> X02060C | D8: =SUM(D222,D436,D650,D864,D1080) -> 9600 | E8: =SUM(E222,E436,E650,E864,E1080) -> 7200 | F8: =SUM(F222,F436,F650,F864,F1080) -> 2400 | G8: =SUM(G222,G436,G650,G864,G1080) -> 0 | H8: =IF(SUM(H222,H436,H650,H864,H1080)=0,"",SUM(H222,H436,H650,H864,H1080)) | I8: =IF(SUM(I222,I436,I650,I864,I1080)=0,"",SUM(I222,I436,I650,I864,I1080)) | J8: =IF(SUM(J222,J436,J650,J864,J1080)=0,"",SUM(J222,J436,J650,J864,J1080)) -> 7200 | K8: =IF(SUM(K222,K436,K650,K864,K1080)=0,"",SUM(K222,K436,K650,K864,K1080)) -> 2400 | L8: =IF(SUM(L222,L436,L650,L864,L1080)=0,"",SUM(L222,L436,L650,L864,L1080)) | M8: =IF(SUM(M222,M436,M650,M864,M1080)=0,"",SUM(M222,M436,M650,M864,M1080)) | N8: =IF(SUM(N222,N436,N650,N864,N1080)=0,"",SUM(N222,N436,N650,N864,N1080)) | O8: =IF(SUM(O222,O436,O650,O864,O1080)=0,"",SUM(O222,O436,O650,O864,O1080)) | ... AA8: =IF(SUM(AA222,AA436,AA650,AA864,AA1080)=0,"",SUM(AA222,AA436,AA650,AA864,AA1080))
A9: ='CLINs & Ceiling Rates'!B10 -> Senior II Business/Financial/Management Analyst | B9: ='CLINs & Ceiling Rates'!C10 -> Senior II Business/Financial/Management Analyst | C9: =CONCATENATE("X",RIGHT('CLINs & Ceiling Rates'!G10,6)) -> X02060C | D9: =SUM(D223,D437,D651,D865,D1081) -> 9600 | E9: =SUM(E223,E437,E651,E865,E1081) -> 7200 | F9: =SUM(F223,F437,F651,F865,F1081) -> 2400 | G9: =SUM(G223,G437,G651,G865,G1081) -> 0 | H9: =IF(SUM(H223,H437,H651,H865,H1081)=0,"",SUM(H223,H437,H651,H865,H1081)) | I9: =IF(SUM(I223,I437,I651,I865,I1081)=0,"",SUM(I223,I437,I651,I865,I1081)) | J9: =IF(SUM(J223,J437,J651,J865,J1081)=0,"",SUM(J223,J437,J651,J865,J1081)) -> 7200 | K9: =IF(SUM(K223,K437,K651,K865,K1081)=0,"",SUM(K223,K437,K651,K865,K1081)) -> 2400 | L9: =IF(SUM(L223,L437,L651,L865,L1081)=0,"",SUM(L223,L437,L651,L865,L1081)) | M9: =IF(SUM(M223,M437,M651,M865,M1081)=0,"",SUM(M223,M437,M651,M865,M1081)) | N9: =IF(SUM(N223,N437,N651,N865,N1081)=0,"",SUM(N223,N437,N651,N865,N1081)) | O9: =IF(SUM(O223,O437,O651,O865,O1081)=0,"",SUM(O223,O437,O651,O865,O1081)) | ... AA9: =IF(SUM(AA223,AA437,AA651,AA865,AA1081)=0,"",SUM(AA223,AA437,AA651,AA865,AA1081))
A10: ='CLINs & Ceiling Rates'!B11 -> Senior II Business/Financial/Management Analyst | B10: ='CLINs & Ceiling Rates'!C11 -> Senior II Business/Financial/Management Analyst | C10: =CONCATENATE("X",RIGHT('CLINs & Ceiling Rates'!G11,6)) -> X02060C | D10: =SUM(D224,D438,D652,D866,D1082) -> 9600 | E10: =SUM(E224,E438,E652,E866,E1082) -> 7200 | F10: =SUM(F224,F438,F652,F866,F1082) -> 2400 | G10: =SUM(G224,G438,G652,G866,G1082) -> 0 | H10: =IF(SUM(H224,H438,H652,H866,H1082)=0,"",SUM(H224,H438,H652,H866,H1082)) | I10: =IF(SUM(I224,I438,I652,I866,I1082)=0,"",SUM(I224,I438,I652,I866,I1082)) | J10: =IF(SUM(J224,J438,J652,J866,J1082)=0,"",SUM(J224,J438,J652,J866,J1082)) -> 7200 | K10: =IF(SUM(K224,K438,K652,K866,K1082)=0,"",SUM(K224,K438,K652,K866,K1082)) -> 2400 | L10: =IF(SUM(L224,L438,L652,L866,L1082)=0,"",SUM(L224,L438,L652,L866,L1082)) | M10: =IF(SUM(M224,M438,M652,M866,M1082)=0,"",SUM(M224,M438,M652,M866,M1082)) | N10: =IF(SUM(N224,N438,N652,N866,N1082)=0,"",SUM(N224,N438,N652,N866,N1082)) | O10: =IF(SUM(O224,O438,O652,O866,O1082)=0,"",SUM(O224,O438,O652,O866,O1082)) | ... AA10: =IF(SUM(AA224,AA438,AA652,AA866,AA1082)=0,"",SUM(AA224,AA438,AA652,AA866,AA1082))
A11: ='CLINs & Ceiling Rates'!B12 -> Senior I Business/Financial/Management Analyst | B11: ='CLINs & Ceiling Rates'!C12 -> Senior I Business/Financial/Management Analyst | C11: =CONCATENATE("X",RIGHT('CLINs & Ceiling Rates'!G12,6)) -> X02058C | D11: =SUM(D225,D439,D653,D867,D1083) -> 9600 | E11: =SUM(E225,E439,E653,E867,E1083) -> 7200 | F11: =SUM(F225,F439,F653,F867,F1083) -> 2400 | G11: =SUM(G225,G439,G653,G867,G1083) -> 0 | H11: =IF(SUM(H225,H439,H653,H867,H1083)=0,"",SUM(H225,H439,H653,H867,H1083)) | I11: =IF(SUM(I225,I439,I653,I867,I1083)=0,"",SUM(I225,I439,I653,I867,I1083)) | J11: =IF(SUM(J225,J439,J653,J867,J1083)=0,"",SUM(J225,J439,J653,J867,J1083)) -> 7200 | K11: =IF(SUM(K225,K439,K653,K867,K1083)=0,"",SUM(K225,K439,K653,K867,K1083)) -> 2400 | L11: =IF(SUM(L225,L439,L653,L867,L1083)=0,"",SUM(L225,L439,L653,L867,L1083)) | M11: =IF(SUM(M225,M439,M653,M867,M1083)=0,"",SUM(M225,M439,M653,M867,M1083)) | N11: =IF(SUM(N225,N439,N653,N867,N1083)=0,"",SUM(N225,N439,N653,N867,N1083)) | O11: =IF(SUM(O225,O439,O653,O867,O1083)=0,"",SUM(O225,O439,O653,O867,O1083)) | ... AA11: =IF(SUM(AA225,AA439,AA653,AA867,AA1083)=0,"",SUM(AA225,AA439,AA653,AA867,AA1083))
