Workbook
Name AnnualProductiveHours: [1]Instructions!$H$11
Name AnnualProductiveHours: [2]Instructions!$G$13
Name AnnualProductiveHours: [2]Instructions!$G$13
Name AnnualProductiveHours: [2]Instructions!$G$13
Name AnnualProductiveHours: Instructions!$H$12

Sheet Instructions
A1: Instructions
A2: ="Solicitation Number: "&Instructions!H9&"" -> Solicitation Number: W91CRB-25-R-0002
A3: ="Name of Action: "&Instructions!H10 -> Name of Action: Force Development
A4: ="Prime Contractor/Subcontractor Name/Division: "&Instructions!H15 -> Prime Contractor/Subcontractor Name/Division:
A5: ="Period of Performance: "&Instructions!H11 -> Period of Performance:
A6: ="Date of Proposal:"&IF(ISBLANK(Instructions!H18)," TBD",(TEXT(Instructions!H18," mm/dd/yyyy"))) -> Date of Proposal: TBD
G8: Government Inputs
G9: Solicitation Number: | H9: W91CRB-25-R-0002
G10: Name of Action: | H10: Force Development
G11: Period of Performance:
G12: Annual Productive Hours: | H12: =1920 -> 1920
G14: Offeror Inputs
G15: Prime Contractor/Subcontractor Name/Division:
G16: Street Address:
G17: City, State and Zip Code:
G18: Date of Proposal

Sheet Section B
A1: Section B - Supplies or Services Costs and/or Prices
A2: ="Solicitation Number: "&Instructions!H9&"" -> Solicitation Number: W91CRB-25-R-0002
A3: ="Name of Action: "&Instructions!H10 -> Name of Action: Force Development
A4: ="Prime Contractor/Subcontractor Name/Division: "&Instructions!H15 -> Prime Contractor/Subcontractor Name/Division:
A5: ="Period of Performance: "&Instructions!H11 -> Period of Performance:
A6: ="Date of Proposal:"&IF(ISBLANK(Instructions!H18)," TBD",(TEXT(Instructions!H18," mm/dd/yyyy"))) -> Date of Proposal: TBD
A7: (The format below is a sample. Propose in the actual format of the Section B contained in the solicitation)
A9: Base Period
A10: CLIN | B10: SUPPLIES/SERVICES | C10: QTY | D10: UNIT | E10: UNIT PRICE | F10: AMOUNT
A11: 0001 | B11: Transition-In Labor - Base Period (1 Month) | C11: 1 | D11: Each | E11: 0
B12: Labor - CPFF | E12: Cost | F12: ='Phase-in & OES 52.217-8 Labor'!N26 -> 0 | G12: From Labor Worksheet
E13: Fixed Fee | F13: ='Phase-in & OES 52.217-8 Labor'!O26 -> 0
E14: Cost Plus Fixed Fee | F14: =SUM(F12:F13) -> 0
A16: CLIN | B16: SUPPLIES/SERVICES | C16: QTY | D16: UNIT | E16: UNIT PRICE | F16: AMOUNT
A17: 0002 | B17: Regular Labor - Base Period (11 Months) | C17: 1 | D17: Each | E17: 0
B18: Labor - CPFF | E18: Cost | F18: ='Regular Labor Detail'!N26 -> 0 | G18: From Labor Worksheet
E19: Fixed Fee | F19: ='Regular Labor Detail'!O26 -> 0
E20: Cost Plus Fixed Fee | F20: =SUM(F18:F19) -> 0
A22: CLIN | B22: SUPPLIES/SERVICES | C22: QTY | D22: UNIT | E22: UNIT PRICE | F22: AMOUNT
A23: 0005 | B23: Optional Surge Labor - Base Period (FD, PAE, CAA) | C23: 1 | D23: Each | E23: 0
B24: Labor - CPFF | E24: Cost | F24: ='Surge Labor Detail'!N26 -> 0 | G24: From Labor Worksheet
E25: Fixed Fee | F25: ='Surge Labor Detail'!O26 -> 0
E26: Cost Plus Fixed Fee | F26: =SUM(F24:F25) -> 0
A28: CLIN | B28: SUPPLIES/SERVICES | C28: QTY | D28: UNIT | E28: UNIT PRICE | F28: AMOUNT
A29: 0004 | B29: Travel & ODCs Base Period | C29: 1 | D29: Each | E29: 0
B30: COST | D30: ODCs= | F30: ='ODC Cost Detail'!C10 -> 100000 | G30: From Cost Summary Worksheet
D31: Burden/G&A = | E31: ='ODC Cost Detail'!D10 -> 0 | F31: ='ODC Cost Detail'!E10 -> 0 | G31: From Cost Summary WorkWorksheet and ODC Cost Detail WorkWorksheet
D32: Subtotal ODC Ceiling | F32: =SUM(F30:F31) -> 100000
A34: Option Year (OY) 1
A35: CLIN | B35: SUPPLIES/SERVICES | C35: QTY | D35: UNIT | E35: UNIT PRICE | F35: AMOUNT
A36: 1001 | B36: Regular Labor - OY1 | C36: 1 | D36: Each | E36: 0
B37: Labor - CPFF | E37: Cost | F37: ='Regular Labor Detail'!N66 -> 0 | G37: From Labor Worksheet
E38: Fixed Fee | F38: ='Regular Labor Detail'!O66 -> 0
E39: Cost Plus Fixed Fee | F39: =SUM(F37:F38) -> 0
A41: CLIN | B41: SUPPLIES/SERVICES | C41: QTY | D41: UNIT | E41: UNIT PRICE | F41: AMOUNT
A42: 1004 | B42: Optional Surge Labor - OY1 (FD, PAE, CAA) | C42: 1 | D42: Each | E42: 0
B43: Labor - CPFF | E43: Cost | F43: ='Surge Labor Detail'!N66 -> 0 | G43: From Labor Worksheet
E44: Fixed Fee | F44: ='Surge Labor Detail'!O66 -> 0
E45: Cost Plus Fixed Fee | F45: =SUM(F43:F44) -> 0
A47: CLIN | B47: SUPPLIES/SERVICES | C47: QTY | D47: UNIT | E47: UNIT PRICE | F47: AMOUNT
...

Sheet Cost Summary
A1: Cost Summary Spreadsheet
A2: ="Solicitation Number: "&Instructions!H9&"" -> Solicitation Number: W91CRB-25-R-0002
A3: ="Name of Action: "&Instructions!H10 -> Name of Action: Force Development
A4: ="Prime Contractor/Subcontractor Name/Division: "&Instructions!H15 -> Prime Contractor/Subcontractor Name/Division:
A5: ="Period of Performance: "&Instructions!H11 -> Period of Performance:
A6: ="Date of Proposal:"&IF(ISBLANK(Instructions!H18)," TBD",(TEXT(Instructions!H18," mm/dd/yyyy"))) -> Date of Proposal: TBD
A8: =Instructions!H10 -> Force Development | B8: Transition-In | C8: Base period | D8: Option Year 1 | E8: OY2 | F8: OY3 | G8: OY4 | H8: OES IAW FAR 52.217-8 | I8: Total
A9: Labor & Subcontract Labor Hours | B9: ='Phase-in & OES 52.217-8 Labor'!G26 -> 2652 | C9: ='Regular Labor Detail'!G26+'Surge Labor Detail'!G26 -> 120016 | D9: =+'Regular Labor Detail'!$G66+'Surge Labor Detail'!G66 -> 144730 | E9: =+'Regular Labor Detail'!$G86+'Surge Labor Detail'!G86 -> 154130 | F9: =+'Regular Labor Detail'!$G106+'Surge Labor Detail'!G106 -> 161650 | G9: =+'Regular Labor Detail'!$G126+'Surge Labor Detail'!G126 -> 161650 | H9: ='Phase-in & OES 52.217-8 Labor'!G66+'Phase-in & OES 52.217-8 Labor'!G86 -> 80825 | I9: =SUM(B9:H9) -> 825653 | J9: From Labor Cost Detail Worksheet
A10: Direct & Indirect Labor & Subcontract Labor Costs (less G&A) | B10: ='Phase-in & OES 52.217-8 Labor'!L26 -> 0 | C10: ='Regular Labor Detail'!L26+'Surge Labor Detail'!L26 -> 0 | D10: =+'Regular Labor Detail'!$L66+'Surge Labor Detail'!L66 -> 0 | E10: =+'Regular Labor Detail'!$L86+'Surge Labor Detail'!L86 -> 0 | F10: =+'Regular Labor Detail'!$L106+'Surge Labor Detail'!L106 -> 0 | G10: =+'Regular Labor Detail'!$L126+'Surge Labor Detail'!L126 -> 0 | H10: ='Phase-in & OES 52.217-8 Labor'!L66+'Phase-in & OES 52.217-8 Labor'!L86 -> 0 | I10: =SUM(B10:H10) -> 0 | J10: From Labor Cost Detail Worksheet
A11: G&A Costs | B11: ='Phase-in & OES 52.217-8 Labor'!M26 -> 0 | C11: ='Regular Labor Detail'!M26+'Surge Labor Detail'!M26 -> 0 | D11: =+'Regular Labor Detail'!$M66+'Surge Labor Detail'!M66 -> 0 | E11: =+'Regular Labor Detail'!$M86+'Surge Labor Detail'!M86 -> 0 | F11: =+'Regular Labor Detail'!$M106+'Surge Labor Detail'!M106 -> 0 | G11: =+'Regular Labor Detail'!$M126+'Surge Labor Detail'!M126 -> 0 | H11: ='Phase-in & OES 52.217-8 Labor'!M66+'Phase-in & OES 52.217-8 Labor'!M86 -> 0 | I11: =SUM(B11:H11) -> 0 | J11: From Labor Cost Detail Worksheet
A12: Direct & Indirect Labor & Subcontract Labor Costs (Less Fee) | B12: =SUM(B10:B11) -> 0 | C12: =SUM(C10:C11) -> 0 | D12: =SUM(D10:D11) -> 0 | E12: =SUM(E10:E11) -> 0 | F12: =SUM(F10:F11) -> 0 | G12: =SUM(G10:G11) -> 0 | H12: =SUM(H10:H11) -> 0 | I12: =SUM(I10:I11) -> 0
A13: Profit/Fee | B13: ='Phase-in & OES 52.217-8 Labor'!O26 -> 0 | C13: ='Regular Labor Detail'!O26+'Surge Labor Detail'!O26 -> 0 | D13: =+'Regular Labor Detail'!$O66+'Surge Labor Detail'!O66 -> 0 | E13: =+'Regular Labor Detail'!$O86+'Surge Labor Detail'!O86 -> 0 | F13: =+'Regular Labor Detail'!$O106+'Surge Labor Detail'!O106 -> 0 | G13: =+'Regular Labor Detail'!$O126+'Surge Labor Detail'!O126 -> 0 | H13: ='Phase-in & OES 52.217-8 Labor'!O66+'Phase-in & OES 52.217-8 Labor'!O86 -> 0 | I13: =SUM(B13:H13) -> 0 | J13: From Labor Cost Detail Worksheet
A14: Total Cost Plus Fixed Fee (Labor) | B14: =SUM(B12:B13) -> 0 | C14: =SUM(C12:C13) -> 0 | D14: =SUM(D12:D13) -> 0 | E14: =SUM(E12:E13) -> 0 | F14: =SUM(F12:F13) -> 0 | G14: =SUM(G12:G13) -> 0 | H14: =SUM(H12:H13) -> 0 | I14: =SUM(I12:I13) -> 0
A15: Travel & Other Direct Costs (ODCs) | C15: ='ODC Cost Detail'!C10 -> 100000 | D15: =+'ODC Cost Detail'!C11 -> 100000 | E15: =+'ODC Cost Detail'!C12 -> 100000 | F15: =+'ODC Cost Detail'!C13 -> 100000 | G15: =+'ODC Cost Detail'!C14 -> 100000 | H15: ='ODC Cost Detail'!C15 -> 50000 | I15: =SUM(B15:H15) -> 550000 | J15: From ODC Cost Detail Sheet
A16: G&A Burden on ODCs | C16: =+'ODC Cost Detail'!E10 -> 0 | D16: =+'ODC Cost Detail'!E11 -> 0 | E16: =+'ODC Cost Detail'!E12 -> 0 | F16: =+'ODC Cost Detail'!E13 -> 0 | G16: =+'ODC Cost Detail'!E14 -> 0 | H16: ='ODC Cost Detail'!E15 -> 0 | I16: =SUM(B16:H16) -> 0 | J16: From ODC Cost Detail Sheet
A17: Total Cost (Travel & ODCs) | C17: =SUM(C15:C16) -> 100000 | D17: =SUM(D15:D16) -> 100000 | E17: =SUM(E15:E16) -> 100000 | F17: =SUM(F15:F16) -> 100000 | G17: =SUM(G15:G16) -> 100000 | H17: =SUM(H15:H16) -> 50000 | I17: =SUM(I15:I16) -> 550000
A18: Total Cost Plus Fixed Fee | C18: =+C14+C17 -> 100000 | D18: =+D14+D17 -> 100000 | E18: =+E14+E17 -> 100000 | F18: =+F14+F17 -> 100000 | G18: =+G14+G17 -> 100000 | H18: =+H14+H17 -> 50000 | I18: =+I14+I17 -> 550000

Sheet Indirect Rate Summary
A1: Indirect Rate Summary Spreadsheet
A2: ="Solicitation Number: "&Instructions!H9&"" -> Solicitation Number: W91CRB-25-R-0002
A3: ="Name of Action: "&Instructions!H10 -> Name of Action: Force Development
A4: ="Prime Contractor/Subcontractor Name/Division: "&Instructions!H15 -> Prime Contractor/Subcontractor Name/Division:
A5: ="Period of Performance: "&Instructions!H11 -> Period of Performance:
A6: ="Date of Proposal:"&IF(ISBLANK(Instructions!H18)," TBD",(TEXT(Instructions!H18," mm/dd/yyyy"))) -> Date of Proposal: TBD
A8: Entity | B8: Contract Type | C8: Fringe Rate | D8: Overhead Rate | E8: G&A Rate | F8: Proposed Fee Rate | G8: % of Effort Performed by Prime and Subs Based on Labor Hours
A9: Base Year (Including Transition In)
A10: PRIME CONTRACTOR | B10: CPFF | C10: 0 | D10: 0 | E10: 0 | F10: 0 | G10: 0
A11: SUBCONTRACTOR 1 | C11: 0 | D11: 0 | E11: 0 | F11: 0 | G11: 0
A12: SUBCONTRACTOR 2 | C12: 0 | D12: 0 | E12: 0 | F12: 0 | G12: 0
A13: SUBCONTRACTOR 3 | C13: 0 | D13: 0 | E13: 0 | F13: 0 | G13: 0
A14: ETC | C14: 0 | D14: 0 | E14: 0 | F14: 0 | G14: 0
G15: =SUM(G10:G14) -> 0 | H15: (i.e. 100%)
A16: Option Year (OY) 1
A17: PRIME CONTRACTOR | B17: CPFF | C17: 0 | D17: 0 | E17: 0 | F17: 0 | G17: 0
A18: SUBCONTRACTOR 1 | C18: 0 | D18: 0 | E18: 0 | F18: 0 | G18: 0
A19: SUBCONTRACTOR 2 | C19: 0 | D19: 0 | E19: 0 | F19: 0 | G19: 0
A20: SUBCONTRACTOR 3 | C20: 0 | D20: 0 | E20: 0 | F20: 0 | G20: 0
A21: ETC | C21: 0 | D21: 0 | E21: 0 | F21: 0 | G21: 0
G22: =SUM(G17:G21) -> 0 | H22: (i.e. 100%)
A23: OY2
A24: PRIME CONTRACTOR | B24: CPFF | C24: 0 | D24: 0 | E24: 0 | F24: 0 | G24: 0
A25: SUBCONTRACTOR 1 | C25: 0 | D25: 0 | E25: 0 | F25: 0 | G25: 0
A26: SUBCONTRACTOR 2 | C26: 0 | D26: 0 | E26: 0 | F26: 0 | G26: 0
A27: SUBCONTRACTOR 3 | C27: 0 | D27: 0 | E27: 0 | F27: 0 | G27: 0
A28: ETC | C28: 0 | D28: 0 | E28: 0 | F28: 0 | G28: 0
G29: =SUM(G24:G28) -> 0 | H29: (i.e. 100%)
A30: OY3
A31: PRIME CONTRACTOR | B31: CPFF | C31: 0 | D31: 0 | E31: 0 | F31: 0 | G31: 0
A32: SUBCONTRACTOR 1 | C32: 0 | D32: 0 | E32: 0 | F32: 0 | G32: 0
A33: SUBCONTRACTOR 2 | C33: 0 | D33: 0 | E33: 0 | F33: 0 | G33: 0
A34: SUBCONTRACTOR 3 | C34: 0 | D34: 0 | E34: 0 | F34: 0 | G34: 0
A35: ETC | C35: 0 | D35: 0 | E35: 0 | F35: 0 | G35: 0
G36: =SUM(G31:G35) -> 0
A37: OY4
A38: PRIME CONTRACTOR | B38: CPFF | C38: 0 | D38: 0 | E38: 0 | F38: 0 | G38: 0
A39: SUBCONTRACTOR 1 | C39: 0 | D39: 0 | E39: 0 | F39: 0 | G39: 0
A40: SUBCONTRACTOR 2 | C40: 0 | D40: 0 | E40: 0 | F40: 0 | G40: 0
A41: SUBCONTRACTOR 3 | C41: 0 | D41: 0 | E41: 0 | F41: 0 | G41: 0
...

Sheet Direct Labor Rate Schedule
A1: Direct Labor Rate Schedule
A2: ="Solicitation Number: "&Instructions!H9&"" -> Solicitation Number: W91CRB-25-R-0002
A3: ="Name of Action: "&Instructions!H10 -> Name of Action: Force Development
A4: ="Prime Contractor/Subcontractor Name/Division: "&Instructions!H15 -> Prime Contractor/Subcontractor Name/Division:
A5: ="Period of Performance: "&Instructions!H11 -> Period of Performance:
A6: ="Date of Proposal:"&IF(ISBLANK(Instructions!H18)," TBD",(TEXT(Instructions!H18," mm/dd/yyyy"))) -> Date of Proposal: TBD
F8: Base Year and Transition-In | G8: Option Year (OY) 1 | I8: OY2 | K8: OY3 | M8: OY4 and Optional Extension of Services IAW FAR 52.217-8
A9: Labor Categories | B9: Location | C9: Labor Type | D9: SCA Identifier | E9: Cost Realism Basis for Rate Proposed | F9: Proposed Labor Rate | G9: Escalation | H9: Proposed Labor Rate | I9: Escalation | J9: Proposed Labor Rate | K9: Escalation | L9: Proposed Labor Rate | M9: Escalation | N9: Proposed Labor Rate
A11: Program Manager | H11: =IFERROR((ROUND(F11*(1+G11),2)),0) -> 0 | J11: =IFERROR((ROUND(H11*(1+I11),2)),0) -> 0 | L11: =IFERROR((ROUND(J11*(1+K11),2)),0) -> 0 | N11: =IFERROR((ROUND(L11*(1+M11),2)),0) -> 0
A12: Senior Analyst | H12: =IFERROR((ROUND(F12*(1+G12),2)),0) -> 0 | J12: =IFERROR((ROUND(H12*(1+I12),2)),0) -> 0 | L12: =IFERROR((ROUND(J12*(1+K12),2)),0) -> 0 | N12: =IFERROR((ROUND(L12*(1+M12),2)),0) -> 0
A13: Analyst | H13: =IFERROR((ROUND(F13*(1+G13),2)),0) -> 0 | J13: =IFERROR((ROUND(H13*(1+I13),2)),0) -> 0 | L13: =IFERROR((ROUND(J13*(1+K13),2)),0) -> 0 | N13: =IFERROR((ROUND(L13*(1+M13),2)),0) -> 0
A14: Junior Analyst | H14: =IFERROR((ROUND(F14*(1+G14),2)),0) -> 0 | J14: =IFERROR((ROUND(H14*(1+I14),2)),0) -> 0 | L14: =IFERROR((ROUND(J14*(1+K14),2)),0) -> 0 | N14: =IFERROR((ROUND(L14*(1+M14),2)),0) -> 0
A15: Senior Operations Research Analyst | H15: =IFERROR((ROUND(F15*(1+G15),2)),0) -> 0 | J15: =IFERROR((ROUND(H15*(1+I15),2)),0) -> 0 | L15: =IFERROR((ROUND(J15*(1+K15),2)),0) -> 0 | N15: =IFERROR((ROUND(L15*(1+M15),2)),0) -> 0
A16: Operations Research Analyst | H16: =IFERROR((ROUND(F16*(1+G16),2)),0) -> 0 | J16: =IFERROR((ROUND(H16*(1+I16),2)),0) -> 0 | L16: =IFERROR((ROUND(J16*(1+K16),2)),0) -> 0 | N16: =IFERROR((ROUND(L16*(1+M16),2)),0) -> 0
A17: Graphics Design Senior Analyst | H17: =IFERROR((ROUND(F17*(1+G17),2)),0) -> 0 | J17: =IFERROR((ROUND(H17*(1+I17),2)),0) -> 0 | L17: =IFERROR((ROUND(J17*(1+K17),2)),0) -> 0 | N17: =IFERROR((ROUND(L17*(1+M17),2)),0) -> 0
A18: Force Documentation Senior Analyst | H18: =IFERROR((ROUND(F18*(1+G18),2)),0) -> 0 | J18: =IFERROR((ROUND(H18*(1+I18),2)),0) -> 0 | L18: =IFERROR((ROUND(J18*(1+K18),2)),0) -> 0 | N18: =IFERROR((ROUND(L18*(1+M18),2)),0) -> 0
H19: =IFERROR((ROUND(F19*(1+G19),2)),0) -> 0 | J19: =IFERROR((ROUND(H19*(1+I19),2)),0) -> 0 | L19: =IFERROR((ROUND(J19*(1+K19),2)),0) -> 0 | N19: =IFERROR((ROUND(L19*(1+M19),2)),0) -> 0
H20: =IFERROR((ROUND(F20*(1+G20),2)),0) -> 0 | J20: =IFERROR((ROUND(H20*(1+I20),2)),0) -> 0 | L20: =IFERROR((ROUND(J20*(1+K20),2)),0) -> 0 | N20: =IFERROR((ROUND(L20*(1+M20),2)),0) -> 0
H21: =IFERROR((ROUND(F21*(1+G21),2)),0) -> 0 | J21: =IFERROR((ROUND(H21*(1+I21),2)),0) -> 0 | L21: =IFERROR((ROUND(J21*(1+K21),2)),0) -> 0 | N21: =IFERROR((ROUND(L21*(1+M21),2)),0) -> 0
H22: =IFERROR((ROUND(F22*(1+G22),2)),0) -> 0 | J22: =IFERROR((ROUND(H22*(1+I22),2)),0) -> 0 | L22: =IFERROR((ROUND(J22*(1+K22),2)),0) -> 0 | N22: =IFERROR((ROUND(L22*(1+M22),2)),0) -> 0
H23: =IFERROR((ROUND(F23*(1+G23),2)),0) -> 0 | J23: =IFERROR((ROUND(H23*(1+I23),2)),0) -> 0 | L23: =IFERROR((ROUND(J23*(1+K23),2)),0) -> 0 | N23: =IFERROR((ROUND(L23*(1+M23),2)),0) -> 0
H24: =IFERROR((ROUND(F24*(1+G24),2)),0) -> 0 | J24: =IFERROR((ROUND(H24*(1+I24),2)),0) -> 0 | L24: =IFERROR((ROUND(J24*(1+K24),2)),0) -> 0 | N24: =IFERROR((ROUND(L24*(1+M24),2)),0) -> 0

Sheet Regular Labor Detail
A1: Labor Cost Detail Spreadsheet
A2: ="Solicitation Number: "&Instructions!H9&"" -> Solicitation Number: W91CRB-25-R-0002
A3: ="Name of Action: "&Instructions!H10 -> Name of Action: Force Development
A4: ="Prime Contractor/Subcontractor Name/Division: "&Instructions!H15 -> Prime Contractor/Subcontractor Name/Division:
A5: ="Period of Performance: "&Instructions!H11 -> Period of Performance:
A6: ="Date of Proposal:"&IF(ISBLANK(Instructions!H18)," TBD",(TEXT(Instructions!H18," mm/dd/yyyy"))) -> Date of Proposal: TBD
A7: ="Annual Productive Hours: "&AnnualProductiveHours -> Annual Productive Hours: 1920
G9: Direct Labor | I9: Indirect Cost
C10: CLIN 0001-2 Base Period (11 Months) | I10: ='Indirect Rate Summary'!C10 -> 0 | J10: ='Indirect Rate Summary'!D10 -> 0 | M10: ='Indirect Rate Summary'!E10 -> 0 | O10: ='Indirect Rate Summary'!F10 -> 0
A11: Location (Note 1) | B11: Labor Type (Note 2) | C11: Labor Categories (Note 3) | D11: Effort To Be Performed By The Prime (P) or Subcontractor (S) (Note 4) | E11: If Column D=S, Enter Name of Subcontractor(s) (Note 5) | F11: FTEs (Note 6) | G11: Total Productive Hours (Note 7) | H11: Hourly Base Pay Rate (Note 8) | I11: Fringe (Note 9) | J11: Overhead (Note 10) | K11: Prime/Sub Hourly Rate Before Application Of Prime G&A & Fee (IF Col C=S Enter Sub Rate) (Note 11) | L11: Total Prime & Sub Labor Before Prime G&A & Fee | M11: G&A (Note 12) | N11: Total Cost | O11: Fee | P11: Total Price | Q11: Proposal Fully Burdened Hourly Billing Rate | R11: Wrap Rate
A12: a | B12: b | C12: c | D12: d | E12: e | F12: f | G12: g | H12: h | I12: i | J12: j | K12: k = h + i + j | L12: l = g x k | M12: m | N12: n = l + o | O12: o | P12: p = n + o | Q12: q = p/g | R12: r = q/h
A13: =IF('Direct Labor Rate Schedule'!$A$10="","",'Direct Labor Rate Schedule'!$A$10)
A14: =IF('Direct Labor Rate Schedule'!B18="","",'Direct Labor Rate Schedule'!B11) | B14: ='Direct Labor Rate Schedule'!C11 -> 0 | C14: ='Direct Labor Rate Schedule'!A11 -> Program Manager | D14: Enter P or S | F14: =(G14/AnnualProductiveHours) -> 0.89791667 | G14: 1724 | H14: ='Direct Labor Rate Schedule'!F11 -> 0 | I14: =ROUND((+H14*$I$10),2) -> 0 | J14: =ROUND((+H14*$J$10),2) -> 0 | K14: =+H14+SUM(I14:J14) -> 0 | L14: =ROUND((+G14*K14),2) -> 0 | M14: =ROUND((+L14*$M$10),2) -> 0 | N14: =SUM(L14:M14) -> 0 | O14: =ROUND((+N14*$O$10),2) -> 0 | P14: =SUM(N14:O14) -> 0 | Q14: =IFERROR((+P14/G14),"") -> 0 | R14: =IFERROR(Q14/H14-1,"")
A15: =IF('Direct Labor Rate Schedule'!B19="","",'Direct Labor Rate Schedule'!B12) | B15: ='Direct Labor Rate Schedule'!C12 -> 0 | C15: ='Direct Labor Rate Schedule'!A12 -> Senior Analyst | D15: Enter P or S | F15: =(G15/AnnualProductiveHours) -> 44.964583 | G15: 86332 | H15: ='Direct Labor Rate Schedule'!F12 -> 0 | I15: =ROUND((+H15*$I$10),2) -> 0 | J15: =ROUND((+H15*$J$10),2) -> 0 | K15: =+H15+SUM(I15:J15) -> 0 | L15: =ROUND((+G15*K15),2) -> 0 | M15: =ROUND((+L15*$M$10),2) -> 0 | N15: =SUM(L15:M15) -> 0 | O15: =ROUND((+N15*$O$10),2) -> 0 | P15: =SUM(N15:O15) -> 0 | Q15: =IFERROR((+P15/G15),"") -> 0 | R15: =IFERROR(Q15/H15-1,"")
A16: =IF('Direct Labor Rate Schedule'!B20="","",'Direct Labor Rate Schedule'!B13) | B16: ='Direct Labor Rate Schedule'!C13 -> 0 | C16: ='Direct Labor Rate Schedule'!A13 -> Analyst | D16: Enter P or S | F16: =(G16/AnnualProductiveHours) -> 2.9375 | G16: 5640 | H16: ='Direct Labor Rate Schedule'!F13 -> 0 | I16: =ROUND((+H16*$I$10),2) -> 0 | J16: =ROUND((+H16*$J$10),2) -> 0 | K16: =+H16+SUM(I16:J16) -> 0 | L16: =ROUND((+G16*K16),2) -> 0 | M16: =ROUND((+L16*$M$10),2) -> 0 | N16: =SUM(L16:M16) -> 0 | O16: =ROUND((+N16*$O$10),2) -> 0 | P16: =SUM(N16:O16) -> 0 | Q16: =IFERROR((+P16/G16),"") -> 0 | R16: =IFERROR(Q16/H16-1,"")
A17: =IF('Direct Labor Rate Schedule'!B21="","",'Direct Labor Rate Schedule'!B14) | B17: ='Direct Labor Rate Schedule'!C14 -> 0 | C17: ='Direct Labor Rate Schedule'!A14 -> Junior Analyst | D17: Enter P or S | F17: =(G17/AnnualProductiveHours) -> 2.9375 | G17: 5640 | H17: ='Direct Labor Rate Schedule'!F14 -> 0 | I17: =ROUND((+H17*$I$10),2) -> 0 | J17: =ROUND((+H17*$J$10),2) -> 0 | K17: =+H17+SUM(I17:J17) -> 0 | L17: =ROUND((+G17*K17),2) -> 0 | M17: =ROUND((+L17*$M$10),2) -> 0 | N17: =SUM(L17:M17) -> 0 | O17: =ROUND((+N17*$O$10),2) -> 0 | P17: =SUM(N17:O17) -> 0 | Q17: =IFERROR((+P17/G17),"") -> 0 | R17: =IFERROR(Q17/H17-1,"")
A18: =IF('Direct Labor Rate Schedule'!B22="","",'Direct Labor Rate Schedule'!B15) | B18: ='Direct Labor Rate Schedule'!C15 -> 0 | C18: ='Direct Labor Rate Schedule'!A15 -> Senior Operations Research Analyst | D18: Enter P or S | F18: =(G18/AnnualProductiveHours) -> 2.9375 | G18: 5640 | H18: ='Direct Labor Rate Schedule'!F15 -> 0 | I18: =ROUND((+H18*$I$10),2) -> 0 | J18: =ROUND((+H18*$J$10),2) -> 0 | K18: =+H18+SUM(I18:J18) -> 0 | L18: =ROUND((+G18*K18),2) -> 0 | M18: =ROUND((+L18*$M$10),2) -> 0 | N18: =SUM(L18:M18) -> 0 | O18: =ROUND((+N18*$O$10),2) -> 0 | P18: =SUM(N18:O18) -> 0 | Q18: =IFERROR((+P18/G18),"") -> 0 | R18: =IFERROR(Q18/H18-1,"")
A19: =IF('Direct Labor Rate Schedule'!B23="","",'Direct Labor Rate Schedule'!B16) | B19: ='Direct Labor Rate Schedule'!C16 -> 0 | C19: ='Direct Labor Rate Schedule'!A16 -> Operations Research Analyst | D19: Enter P or S | F19: =(G19/AnnualProductiveHours) -> 1.9583333 | G19: 3760 | H19: ='Direct Labor Rate Schedule'!F16 -> 0 | I19: =ROUND((+H19*$I$10),2) -> 0 | J19: =ROUND((+H19*$J$10),2) -> 0 | K19: =+H19+SUM(I19:J19) -> 0 | L19: =ROUND((+G19*K19),2) -> 0 | M19: =ROUND((+L19*$M$10),2) -> 0 | N19: =SUM(L19:M19) -> 0 | O19: =ROUND((+N19*$O$10),2) -> 0 | P19: =SUM(N19:O19) -> 0 | Q19: =IFERROR((+P19/G19),"") -> 0 | R19: =IFERROR(Q19/H19-1,"")
A20: =IF('Direct Labor Rate Schedule'!B24="","",'Direct Labor Rate Schedule'!B17) | B20: ='Direct Labor Rate Schedule'!C17 -> 0 | C20: ='Direct Labor Rate Schedule'!A17 -> Graphics Design Senior Analyst | D20: Enter P or S | F20: =(G20/AnnualProductiveHours) -> 0.97916667 | G20: 1880 | H20: ='Direct Labor Rate Schedule'!F17 -> 0 | I20: =ROUND((+H20*$I$10),2) -> 0 | J20: =ROUND((+H20*$J$10),2) -> 0 | K20: =+H20+SUM(I20:J20) -> 0 | L20: =ROUND((+G20*K20),2) -> 0 | M20: =ROUND((+L20*$M$10),2) -> 0 | N20: =SUM(L20:M20) -> 0 | O20: =ROUND((+N20*$O$10),2) -> 0 | P20: =SUM(N20:O20) -> 0 | Q20: =IFERROR((+P20/G20),"") -> 0 | R20: =IFERROR(Q20/H20-1,"")
A21: =IF('Direct Labor Rate Schedule'!B25="","",'Direct Labor Rate Schedule'!B18) | B21: ='Direct Labor Rate Schedule'!C18 -> 0 | C21: ='Direct Labor Rate Schedule'!A18 -> Force Documentation Senior Analyst | D21: Enter P or S | F21: =(G21/AnnualProductiveHours) -> 0.97916667 | G21: 1880 | H21: ='Direct Labor Rate Schedule'!F18 -> 0 | I21: =ROUND((+H21*$I$10),2) -> 0 | J21: =ROUND((+H21*$J$10),2) -> 0 | K21: =+H21+SUM(I21:J21) -> 0 | L21: =ROUND((+G21*K21),2) -> 0 | M21: =ROUND((+L21*$M$10),2) -> 0 | N21: =SUM(L21:M21) -> 0 | O21: =ROUND((+N21*$O$10),2) -> 0 | P21: =SUM(N21:O21) -> 0 | Q21: =IFERROR((+P21/G21),"") -> 0 | R21: =IFERROR(Q21/H21-1,"")
A22: =IF('Direct Labor Rate Schedule'!B26="","",'Direct Labor Rate Schedule'!B19) | B22: ='Direct Labor Rate Schedule'!C19 -> 0 | C22: ='Direct Labor Rate Schedule'!A19 -> 0 | D22: Enter P or S | F22: =(G22/AnnualProductiveHours) -> 0 | G22: 0 | H22: ='Direct Labor Rate Schedule'!F19 -> 0 | I22: =ROUND((+H22*$I$10),2) -> 0 | J22: =ROUND((+H22*$J$10),2) -> 0 | K22: =+H22+SUM(I22:J22) -> 0 | L22: =ROUND((+G22*K22),2) -> 0 | M22: =ROUND((+L22*$M$10),2) -> 0 | N22: =SUM(L22:M22) -> 0 | O22: =ROUND((+N22*$O$10),2) -> 0 | P22: =SUM(N22:O22) -> 0 | Q22: =IFERROR((+P22/G22),"") | R22: =IFERROR(Q22/H22-1,"")
A23: =IF('Direct Labor Rate Schedule'!B27="","",'Direct Labor Rate Schedule'!B20) | B23: ='Direct Labor Rate Schedule'!C20 -> 0 | C23: ='Direct Labor Rate Schedule'!A20 -> 0 | D23: Enter P or S | F23: =(G23/AnnualProductiveHours) -> 0 | G23: 0 | H23: ='Direct Labor Rate Schedule'!F20 -> 0 | I23: =ROUND((+H23*$I$10),2) -> 0 | J23: =ROUND((+H23*$J$10),2) -> 0 | K23: =+H23+SUM(I23:J23) -> 0 | L23: =ROUND((+G23*K23),2) -> 0 | M23: =ROUND((+L23*$M$10),2) -> 0 | N23: =SUM(L23:M23) -> 0 | O23: =ROUND((+N23*$O$10),2) -> 0 | P23: =SUM(N23:O23) -> 0 | Q23: =IFERROR((+P23/G23),"") | R23: =IFERROR(Q23/H23-1,"")
A24: =IF('Direct Labor Rate Schedule'!B28="","",'Direct Labor Rate Schedule'!B21) | B24: ='Direct Labor Rate Schedule'!C21 -> 0 | C24: ='Direct Labor Rate Schedule'!A21 -> 0 | D24: Enter P or S | F24: =(G24/AnnualProductiveHours) -> 0 | G24: 0 | H24: ='Direct Labor Rate Schedule'!F21 -> 0 | I24: =ROUND((+H24*$I$10),2) -> 0 | J24: =ROUND((+H24*$J$10),2) -> 0 | K24: =+H24+SUM(I24:J24) -> 0 | L24: =ROUND((+G24*K24),2) -> 0 | M24: =ROUND((+L24*$M$10),2) -> 0 | N24: =SUM(L24:M24) -> 0 | O24: =ROUND((+N24*$O$10),2) -> 0 | P24: =SUM(N24:O24) -> 0 | Q24: =IFERROR((+P24/G24),"") | R24: =IFERROR(Q24/H24-1,"")
A25: =IF('Direct Labor Rate Schedule'!B29="","",'Direct Labor Rate Schedule'!B22) | B25: ='Direct Labor Rate Schedule'!C22 -> 0 | C25: ='Direct Labor Rate Schedule'!A22 -> 0 | D25: Enter P or S | F25: =(G25/AnnualProductiveHours) -> 0 | G25: 0 | H25: ='Direct Labor Rate Schedule'!F22 -> 0 | I25: =ROUND((+H25*$I$10),2) -> 0 | J25: =ROUND((+H25*$J$10),2) -> 0 | K25: =+H25+SUM(I25:J25) -> 0 | L25: =ROUND((+G25*K25),2) -> 0 | M25: =ROUND((+L25*$M$10),2) -> 0 | N25: =SUM(L25:M25) -> 0 | O25: =ROUND((+N25*$O$10),2) -> 0 | P25: =SUM(N25:O25) -> 0 | Q25: =IFERROR((+P25/G25),"") | R25: =IFERROR(Q25/H25-1,"")
A26: Total: | F26: =SUM(F14:F25) -> 58.591667 | G26: =SUM(G14:G25) -> 112496 | H26: =SUMPRODUCT(H14:H25,$G14:$G25) -> 0 | I26: =SUMPRODUCT(I14:I25,$G14:$G25) -> 0 | J26: =SUMPRODUCT(J14:J25,$G14:$G25) -> 0 | K26: =SUMPRODUCT(K14:K25,$G14:$G25) -> 0 | L26: =SUM(L14:L25) -> 0 | M26: =SUM(M14:M25) -> 0 | N26: =SUM(N14:N25) -> 0 | O26: =SUM(O14:O25) -> 0 | P26: =SUM(P14:P25) -> 0 | Q26: =SUMPRODUCT(Q14:Q25,$G14:$G25) -> 0
A27: Weighted Average: | G27: =G26/SUM(F14:F25) -> 1920 | H27: =H26/$G26 -> 0 | I27: =I26/$G26 -> 0 | J27: =J26/$G26 -> 0 | K27: =K26/$G26 -> 0 | L27: =L26/$G26 -> 0 | M27: =M26/$G26 -> 0 | N27: =N26/$G26 -> 0 | O27: =O26/$G26 -> 0 | ... Q27: =Q26/$G26 -> 0 | R27: =Q27/H27 -> #DIV/0!
G29: Direct Cost | I29: Indirect Cost
I30: ='Indirect Rate Summary'!C10 -> 0 | J30: ='Indirect Rate Summary'!D10 -> 0 | M30: ='Indirect Rate Summary'!E10 -> 0 | O30: ='Indirect Rate Summary'!F10 -> 0
A31: =+A11 -> Location (Note 1) | B31: =+B11 -> Labor Type (Note 2) | C31: =+C11 -> Labor Categories (Note 3) | D31: =+D11 -> Effort To Be Performed By The Prime (P) or Subcontractor (S) (Note 4) | E31: =+E11 -> If Column D=S, Enter Name of Subcontractor(s) (Note 5) | F31: =+F11 -> FTEs (Note 6) | G31: =+G11 -> Total Productive Hours (Note 7) | H31: =+H11 -> Hourly Base Pay Rate (Note 8) | ... R31: =+R11 -> Wrap Rate
A32: =+A12 -> a | B32: =+B12 -> b | C32: =+C12 -> c | D32: =+D12 -> d | E32: =+E12 -> e | F32: =+F12 -> f | G32: =+G12 -> g | H32: =+H12 -> h | ... R32: =+R12 -> r = q/h
A33: =IF('Direct Labor Rate Schedule'!$A$10="","",'Direct Labor Rate Schedule'!$A$10)
A34: =A14 | B34: =B14 -> 0 | C34: =C14 -> Program Manager | D34: Enter P or S | F34: =(G34/AnnualProductiveHours)*(12/11) -> 0 | H34: ='Direct Labor Rate Schedule'!F11 -> 0 | I34: =ROUND((+H34*$I$30),2) -> 0 | J34: =ROUND((+H34*$J$30),2) -> 0 | K34: =+H34+SUM(I34:J34) -> 0 | L34: =ROUND((+G34*K34),2) -> 0 | M34: =ROUND((+L34*$M$30),2) -> 0 | N34: =SUM(L34:M34) -> 0 | O34: =ROUND((+N34*$O$30),2) -> 0 | P34: =SUM(N34:O34) -> 0 | Q34: =IFERROR((+P34/G34),"") | R34: =IFERROR(Q34/H34-1,"")
A35: =A15 | B35: =B15 -> 0 | C35: =C15 -> Senior Analyst | D35: Enter P or S | F35: =(G35/AnnualProductiveHours)*(12/11) -> 0 | H35: ='Direct Labor Rate Schedule'!F12 -> 0 | I35: =ROUND((+H35*$I$30),2) -> 0 | J35: =ROUND((+H35*$J$30),2) -> 0 | K35: =+H35+SUM(I35:J35) -> 0 | L35: =ROUND((+G35*K35),2) -> 0 | M35: =ROUND((+L35*$M$30),2) -> 0 | N35: =SUM(L35:M35) -> 0 | O35: =ROUND((+N35*$O$30),2) -> 0 | P35: =SUM(N35:O35) -> 0 | Q35: =IFERROR((+P35/G35),"") | R35: =IFERROR(Q35/H35-1,"")
A36: =A16 | B36: =B16 -> 0 | C36: =C16 -> Analyst | D36: Enter P or S | F36: =(G36/AnnualProductiveHours)*(12/11) -> 0 | H36: ='Direct Labor Rate Schedule'!F13 -> 0 | I36: =ROUND((+H36*$I$30),2) -> 0 | J36: =ROUND((+H36*$J$30),2) -> 0 | K36: =+H36+SUM(I36:J36) -> 0 | L36: =ROUND((+G36*K36),2) -> 0 | M36: =ROUND((+L36*$M$30),2) -> 0 | N36: =SUM(L36:M36) -> 0 | O36: =ROUND((+N36*$O$30),2) -> 0 | P36: =SUM(N36:O36) -> 0 | Q36: =IFERROR((+P36/G36),"") | R36: =IFERROR(Q36/H36-1,"")
A37: =A17 | B37: =B17 -> 0 | C37: =C17 -> Junior Analyst | D37: Enter P or S | F37: =(G37/AnnualProductiveHours)*(12/11) -> 0 | H37: ='Direct Labor Rate Schedule'!F14 -> 0 | I37: =ROUND((+H37*$I$30),2) -> 0 | J37: =ROUND((+H37*$J$30),2) -> 0 | K37: =+H37+SUM(I37:J37) -> 0 | L37: =ROUND((+G37*K37),2) -> 0 | M37: =ROUND((+L37*$M$30),2) -> 0 | N37: =SUM(L37:M37) -> 0 | O37: =ROUND((+N37*$O$30),2) -> 0 | P37: =SUM(N37:O37) -> 0 | Q37: =IFERROR((+P37/G37),"") | R37: =IFERROR(Q37/H37-1,"")
A38: =A18 | B38: =B18 -> 0 | C38: =C18 -> Senior Operations Research Analyst | D38: Enter P or S | F38: =(G38/AnnualProductiveHours)*(12/11) -> 0 | H38: ='Direct Labor Rate Schedule'!F15 -> 0 | I38: =ROUND((+H38*$I$30),2) -> 0 | J38: =ROUND((+H38*$J$30),2) -> 0 | K38: =+H38+SUM(I38:J38) -> 0 | L38: =ROUND((+G38*K38),2) -> 0 | M38: =ROUND((+L38*$M$30),2) -> 0 | N38: =SUM(L38:M38) -> 0 | O38: =ROUND((+N38*$O$30),2) -> 0 | P38: =SUM(N38:O38) -> 0 | Q38: =IFERROR((+P38/G38),"") | R38: =IFERROR(Q38/H38-1,"")
A39: =A19 | B39: =B19 -> 0 | C39: =C19 -> Operations Research Analyst | D39: Enter P or S | F39: =(G39/AnnualProductiveHours)*(12/11) -> 0 | H39: ='Direct Labor Rate Schedule'!F16 -> 0 | I39: =ROUND((+H39*$I$30),2) -> 0 | J39: =ROUND((+H39*$J$30),2) -> 0 | K39: =+H39+SUM(I39:J39) -> 0 | L39: =ROUND((+G39*K39),2) -> 0 | M39: =ROUND((+L39*$M$30),2) -> 0 | N39: =SUM(L39:M39) -> 0 | O39: =ROUND((+N39*$O$30),2) -> 0 | P39: =SUM(N39:O39) -> 0 | Q39: =IFERROR((+P39/G39),"") | R39: =IFERROR(Q39/H39-1,"")
A40: =A20 | B40: =B20 -> 0 | C40: =C20 -> Graphics Design Senior Analyst | D40: Enter P or S | F40: =(G40/AnnualProductiveHours)*(12/11) -> 0 | H40: ='Direct Labor Rate Schedule'!F17 -> 0 | I40: =ROUND((+H40*$I$30),2) -> 0 | J40: =ROUND((+H40*$J$30),2) -> 0 | K40: =+H40+SUM(I40:J40) -> 0 | L40: =ROUND((+G40*K40),2) -> 0 | M40: =ROUND((+L40*$M$30),2) -> 0 | N40: =SUM(L40:M40) -> 0 | O40: =ROUND((+N40*$O$30),2) -> 0 | P40: =SUM(N40:O40) -> 0 | Q40: =IFERROR((+P40/G40),"") | R40: =IFERROR(Q40/H40-1,"")
A41: =A21 | B41: =B21 -> 0 | C41: =C21 -> Force Documentation Senior Analyst | D41: Enter P or S | F41: =(G41/AnnualProductiveHours)*(12/11) -> 0 | H41: ='Direct Labor Rate Schedule'!F18 -> 0 | I41: =ROUND((+H41*$I$30),2) -> 0 | J41: =ROUND((+H41*$J$30),2) -> 0 | K41: =+H41+SUM(I41:J41) -> 0 | L41: =ROUND((+G41*K41),2) -> 0 | M41: =ROUND((+L41*$M$30),2) -> 0 | N41: =SUM(L41:M41) -> 0 | O41: =ROUND((+N41*$O$30),2) -> 0 | P41: =SUM(N41:O41) -> 0 | Q41: =IFERROR((+P41/G41),"") | R41: =IFERROR(Q41/H41-1,"")
A42: =A22 | B42: =B22 -> 0 | C42: =C22 -> 0 | D42: Enter P or S | F42: =(G42/AnnualProductiveHours)*(12/11) -> 0 | H42: ='Direct Labor Rate Schedule'!F19 -> 0 | I42: =ROUND((+H42*$I$30),2) -> 0 | J42: =ROUND((+H42*$J$30),2) -> 0 | K42: =+H42+SUM(I42:J42) -> 0 | L42: =ROUND((+G42*K42),2) -> 0 | M42: =ROUND((+L42*$M$30),2) -> 0 | N42: =SUM(L42:M42) -> 0 | O42: =ROUND((+N42*$O$30),2) -> 0 | P42: =SUM(N42:O42) -> 0 | Q42: =IFERROR((+P42/G42),"") | R42: =IFERROR(Q42/H42-1,"")
...

Sheet Surge Labor Detail
A1: Labor Cost Detail Spreadsheet
A2: ="Solicitation Number: "&Instructions!H9&"" -> Solicitation Number: W91CRB-25-R-0002
A3: ="Name of Action: "&Instructions!H10 -> Name of Action: Force Development
A4: ="Prime Contractor/Subcontractor Name/Division: "&Instructions!H15 -> Prime Contractor/Subcontractor Name/Division:
A5: ="Period of Performance: "&Instructions!H11 -> Period of Performance:
A6: ="Date of Proposal:"&IF(ISBLANK(Instructions!H18)," TBD",(TEXT(Instructions!H18," mm/dd/yyyy"))) -> Date of Proposal: TBD
A7: ="Annual Productive Hours: "&AnnualProductiveHours -> Annual Productive Hours: 1920
G9: Direct Labor | I9: Indirect Cost
C10: CLIN 0002 - Base Period Surge Option (FD, PAE, CAA) | I10: ='Indirect Rate Summary'!C10 -> 0 | J10: ='Indirect Rate Summary'!D10 -> 0 | M10: ='Indirect Rate Summary'!E10 -> 0 | O10: ='Indirect Rate Summary'!F10 -> 0
A11: Location (Note 1) | B11: Labor Type (Note 2) | C11: Labor Categories (Note 3) | D11: Effort To Be Performed By The Prime (P) or Subcontractor (S) (Note 4) | E11: If Column D=S, Enter Name of Subcontractor(s) (Note 5) | F11: FTEs (Note 6) | G11: Total Productive Hours (Note 7) | H11: Hourly Base Pay Rate (Note 8) | I11: Fringe (Note 9) | J11: Overhead (Note 10) | K11: Prime/Sub Hourly Rate Before Application Of Prime G&A & Fee (IF Col C=S Enter Sub Rate) (Note 11) | L11: Total Prime & Sub Labor Before Prime G&A & Fee | M11: G&A (Note 12) | N11: Total Cost | O11: Fee | P11: Total Price | Q11: Proposal Fully Burdened Hourly Billing Rate | R11: Wrap Rate
A12: a | B12: b | C12: c | D12: d | E12: e | F12: f | G12: g | H12: h | I12: i | J12: j | K12: k = h + i + j | L12: l = g x k | M12: m | N12: n = l + o | O12: o | P12: p = n + o | Q12: q = p/g | R12: r = q/h
A13: =IF('Direct Labor Rate Schedule'!$A$10="","",'Direct Labor Rate Schedule'!$A$10)
A14: =IF('Direct Labor Rate Schedule'!B18="","",'Direct Labor Rate Schedule'!B11) | B14: ='Direct Labor Rate Schedule'!C11 -> 0 | C14: ='Direct Labor Rate Schedule'!A11 -> Program Manager | D14: Enter P or S | F14: =(G14/AnnualProductiveHours) -> 0 | G14: 0 | H14: ='Direct Labor Rate Schedule'!F11 -> 0 | I14: =ROUND((+H14*$I$10),2) -> 0 | J14: =ROUND((+H14*$J$10),2) -> 0 | K14: =+H14+SUM(I14:J14) -> 0 | L14: =ROUND((+G14*K14),2) -> 0 | M14: =ROUND((+L14*$M$10),2) -> 0 | N14: =SUM(L14:M14) -> 0 | O14: =ROUND((+N14*$O$10),2) -> 0 | P14: =SUM(N14:O14) -> 0 | Q14: =IFERROR((+P14/G14),"") | R14: =IFERROR(Q14/H14-1,"")
A15: =IF('Direct Labor Rate Schedule'!B19="","",'Direct Labor Rate Schedule'!B12) | B15: ='Direct Labor Rate Schedule'!C12 -> 0 | C15: ='Direct Labor Rate Schedule'!A12 -> Senior Analyst | D15: Enter P or S | F15: =(G15/AnnualProductiveHours) -> 0.97916667 | G15: 1880 | H15: ='Direct Labor Rate Schedule'!F12 -> 0 | I15: =ROUND((+H15*$I$10),2) -> 0 | J15: =ROUND((+H15*$J$10),2) -> 0 | K15: =+H15+SUM(I15:J15) -> 0 | L15: =ROUND((+G15*K15),2) -> 0 | M15: =ROUND((+L15*$M$10),2) -> 0 | N15: =SUM(L15:M15) -> 0 | O15: =ROUND((+N15*$O$10),2) -> 0 | P15: =SUM(N15:O15) -> 0 | Q15: =IFERROR((+P15/G15),"") -> 0 | R15: =IFERROR(Q15/H15-1,"")
A16: =IF('Direct Labor Rate Schedule'!B20="","",'Direct Labor Rate Schedule'!B13) | B16: ='Direct Labor Rate Schedule'!C13 -> 0 | C16: ='Direct Labor Rate Schedule'!A13 -> Analyst | D16: Enter P or S | F16: =(G16/AnnualProductiveHours) -> 0.97916667 | G16: 1880 | H16: ='Direct Labor Rate Schedule'!F13 -> 0 | I16: =ROUND((+H16*$I$10),2) -> 0 | J16: =ROUND((+H16*$J$10),2) -> 0 | K16: =+H16+SUM(I16:J16) -> 0 | L16: =ROUND((+G16*K16),2) -> 0 | M16: =ROUND((+L16*$M$10),2) -> 0 | N16: =SUM(L16:M16) -> 0 | O16: =ROUND((+N16*$O$10),2) -> 0 | P16: =SUM(N16:O16) -> 0 | Q16: =IFERROR((+P16/G16),"") -> 0 | R16: =IFERROR(Q16/H16-1,"")
A17: =IF('Direct Labor Rate Schedule'!B21="","",'Direct Labor Rate Schedule'!B14) | B17: ='Direct Labor Rate Schedule'!C14 -> 0 | C17: ='Direct Labor Rate Schedule'!A14 -> Junior Analyst | D17: Enter P or S | F17: =(G17/AnnualProductiveHours) -> 0 | G17: 0 | H17: ='Direct Labor Rate Schedule'!F14 -> 0 | I17: =ROUND((+H17*$I$10),2) -> 0 | J17: =ROUND((+H17*$J$10),2) -> 0 | K17: =+H17+SUM(I17:J17) -> 0 | L17: =ROUND((+G17*K17),2) -> 0 | M17: =ROUND((+L17*$M$10),2) -> 0 | N17: =SUM(L17:M17) -> 0 | O17: =ROUND((+N17*$O$10),2) -> 0 | P17: =SUM(N17:O17) -> 0 | Q17: =IFERROR((+P17/G17),"") | R17: =IFERROR(Q17/H17-1,"")
A18: =IF('Direct Labor Rate Schedule'!B22="","",'Direct Labor Rate Schedule'!B15) | B18: ='Direct Labor Rate Schedule'!C15 -> 0 | C18: ='Direct Labor Rate Schedule'!A15 -> Senior Operations Research Analyst | D18: Enter P or S | F18: =(G18/AnnualProductiveHours) -> 0.97916667 | G18: 1880 | H18: ='Direct Labor Rate Schedule'!F15 -> 0 | I18: =ROUND((+H18*$I$10),2) -> 0 | J18: =ROUND((+H18*$J$10),2) -> 0 | K18: =+H18+SUM(I18:J18) -> 0 | L18: =ROUND((+G18*K18),2) -> 0 | M18: =ROUND((+L18*$M$10),2) -> 0 | N18: =SUM(L18:M18) -> 0 | O18: =ROUND((+N18*$O$10),2) -> 0 | P18: =SUM(N18:O18) -> 0 | Q18: =IFERROR((+P18/G18),"") -> 0 | R18: =IFERROR(Q18/H18-1,"")
A19: =IF('Direct Labor Rate Schedule'!B23="","",'Direct Labor Rate Schedule'!B16) | B19: ='Direct Labor Rate Schedule'!C16 -> 0 | C19: ='Direct Labor Rate Schedule'!A16 -> Operations Research Analyst | D19: Enter P or S | F19: =(G19/AnnualProductiveHours) -> 0.97916667 | G19: 1880 | H19: ='Direct Labor Rate Schedule'!F16 -> 0 | I19: =ROUND((+H19*$I$10),2) -> 0 | J19: =ROUND((+H19*$J$10),2) -> 0 | K19: =+H19+SUM(I19:J19) -> 0 | L19: =ROUND((+G19*K19),2) -> 0 | M19: =ROUND((+L19*$M$10),2) -> 0 | N19: =SUM(L19:M19) -> 0 | O19: =ROUND((+N19*$O$10),2) -> 0 | P19: =SUM(N19:O19) -> 0 | Q19: =IFERROR((+P19/G19),"") -> 0 | R19: =IFERROR(Q19/H19-1,"")
A20: =IF('Direct Labor Rate Schedule'!B24="","",'Direct Labor Rate Schedule'!B17) | B20: ='Direct Labor Rate Schedule'!C17 -> 0 | C20: ='Direct Labor Rate Schedule'!A17 -> Graphics Design Senior Analyst | D20: Enter P or S | F20: =(G20/AnnualProductiveHours) -> 0 | G20: 0 | H20: ='Direct Labor Rate Schedule'!F17 -> 0 | I20: =ROUND((+H20*$I$10),2) -> 0 | J20: =ROUND((+H20*$J$10),2) -> 0 | K20: =+H20+SUM(I20:J20) -> 0 | L20: =ROUND((+G20*K20),2) -> 0 | M20: =ROUND((+L20*$M$10),2) -> 0 | N20: =SUM(L20:M20) -> 0 | O20: =ROUND((+N20*$O$10),2) -> 0 | P20: =SUM(N20:O20) -> 0 | Q20: =IFERROR((+P20/G20),"") | R20: =IFERROR(Q20/H20-1,"")
A21: =IF('Direct Labor Rate Schedule'!B25="","",'Direct Labor Rate Schedule'!B18) | B21: ='Direct Labor Rate Schedule'!C18 -> 0 | C21: ='Direct Labor Rate Schedule'!A18 -> Force Documentation Senior Analyst | D21: Enter P or S | F21: =(G21/AnnualProductiveHours) -> 0 | G21: 0 | H21: ='Direct Labor Rate Schedule'!F18 -> 0 | I21: =ROUND((+H21*$I$10),2) -> 0 | J21: =ROUND((+H21*$J$10),2) -> 0 | K21: =+H21+SUM(I21:J21) -> 0 | L21: =ROUND((+G21*K21),2) -> 0 | M21: =ROUND((+L21*$M$10),2) -> 0 | N21: =SUM(L21:M21) -> 0 | O21: =ROUND((+N21*$O$10),2) -> 0 | P21: =SUM(N21:O21) -> 0 | Q21: =IFERROR((+P21/G21),"") | R21: =IFERROR(Q21/H21-1,"")
A22: =IF('Direct Labor Rate Schedule'!B26="","",'Direct Labor Rate Schedule'!B19) | B22: ='Direct Labor Rate Schedule'!C19 -> 0 | C22: ='Direct Labor Rate Schedule'!A19 -> 0 | D22: Enter P or S | F22: =(G22/AnnualProductiveHours) -> 0 | G22: 0 | H22: ='Direct Labor Rate Schedule'!F19 -> 0 | I22: =ROUND((+H22*$I$10),2) -> 0 | J22: =ROUND((+H22*$J$10),2) -> 0 | K22: =+H22+SUM(I22:J22) -> 0 | L22: =ROUND((+G22*K22),2) -> 0 | M22: =ROUND((+L22*$M$10),2) -> 0 | N22: =SUM(L22:M22) -> 0 | O22: =ROUND((+N22*$O$10),2) -> 0 | P22: =SUM(N22:O22) -> 0 | Q22: =IFERROR((+P22/G22),"") | R22: =IFERROR(Q22/H22-1,"")
A23: =IF('Direct Labor Rate Schedule'!B27="","",'Direct Labor Rate Schedule'!B20) | B23: ='Direct Labor Rate Schedule'!C20 -> 0 | C23: ='Direct Labor Rate Schedule'!A20 -> 0 | D23: Enter P or S | F23: =(G23/AnnualProductiveHours) -> 0 | G23: 0 | H23: ='Direct Labor Rate Schedule'!F20 -> 0 | I23: =ROUND((+H23*$I$10),2) -> 0 | J23: =ROUND((+H23*$J$10),2) -> 0 | K23: =+H23+SUM(I23:J23) -> 0 | L23: =ROUND((+G23*K23),2) -> 0 | M23: =ROUND((+L23*$M$10),2) -> 0 | N23: =SUM(L23:M23) -> 0 | O23: =ROUND((+N23*$O$10),2) -> 0 | P23: =SUM(N23:O23) -> 0 | Q23: =IFERROR((+P23/G23),"") | R23: =IFERROR(Q23/H23-1,"")
A24: =IF('Direct Labor Rate Schedule'!B28="","",'Direct Labor Rate Schedule'!B21) | B24: ='Direct Labor Rate Schedule'!C21 -> 0 | C24: ='Direct Labor Rate Schedule'!A21 -> 0 | D24: Enter P or S | F24: =(G24/AnnualProductiveHours) -> 0 | G24: 0 | H24: ='Direct Labor Rate Schedule'!F21 -> 0 | I24: =ROUND((+H24*$I$10),2) -> 0 | J24: =ROUND((+H24*$J$10),2) -> 0 | K24: =+H24+SUM(I24:J24) -> 0 | L24: =ROUND((+G24*K24),2) -> 0 | M24: =ROUND((+L24*$M$10),2) -> 0 | N24: =SUM(L24:M24) -> 0 | O24: =ROUND((+N24*$O$10),2) -> 0 | P24: =SUM(N24:O24) -> 0 | Q24: =IFERROR((+P24/G24),"") | R24: =IFERROR(Q24/H24-1,"")
A25: =IF('Direct Labor Rate Schedule'!B29="","",'Direct Labor Rate Schedule'!B22) | B25: ='Direct Labor Rate Schedule'!C22 -> 0 | C25: ='Direct Labor Rate Schedule'!A22 -> 0 | D25: Enter P or S | F25: =(G25/AnnualProductiveHours) -> 0 | G25: 0 | H25: ='Direct Labor Rate Schedule'!F22 -> 0 | I25: =ROUND((+H25*$I$10),2) -> 0 | J25: =ROUND((+H25*$J$10),2) -> 0 | K25: =+H25+SUM(I25:J25) -> 0 | L25: =ROUND((+G25*K25),2) -> 0 | M25: =ROUND((+L25*$M$10),2) -> 0 | N25: =SUM(L25:M25) -> 0 | O25: =ROUND((+N25*$O$10),2) -> 0 | P25: =SUM(N25:O25) -> 0 | Q25: =IFERROR((+P25/G25),"") | R25: =IFERROR(Q25/H25-1,"")
A26: Total: | F26: =SUM(F14:F25) -> 3.9166667 | G26: =SUM(G14:G25) -> 7520 | H26: =SUMPRODUCT(H14:H25,$G14:$G25) -> 0 | I26: =SUMPRODUCT(I14:I25,$G14:$G25) -> 0 | J26: =SUMPRODUCT(J14:J25,$G14:$G25) -> 0 | K26: =SUMPRODUCT(K14:K25,$G14:$G25) -> 0 | L26: =SUM(L14:L25) -> 0 | M26: =SUM(M14:M25) -> 0 | N26: =SUM(N14:N25) -> 0 | O26: =SUM(O14:O25) -> 0 | P26: =SUM(P14:P25) -> 0 | Q26: =SUMPRODUCT(Q14:Q25,$G14:$G25) -> 0
A27: Weighted Average: | G27: =G26/SUM(F14:F25) -> 1920 | H27: =H26/$G26 -> 0 | I27: =I26/$G26 -> 0 | J27: =J26/$G26 -> 0 | K27: =K26/$G26 -> 0 | L27: =L26/$G26 -> 0 | M27: =M26/$G26 -> 0 | N27: =N26/$G26 -> 0 | O27: =O26/$G26 -> 0 | ... Q27: =Q26/$G26 -> 0 | R27: =Q27/H27 -> #DIV/0!
G29: Direct Cost | I29: Indirect Cost
I30: ='Indirect Rate Summary'!C10 -> 0 | J30: ='Indirect Rate Summary'!D10 -> 0 | M30: ='Indirect Rate Summary'!E10 -> 0 | O30: ='Indirect Rate Summary'!F10 -> 0
A31: =+A11 -> Location (Note 1) | B31: =+B11 -> Labor Type (Note 2) | C31: =+C11 -> Labor Categories (Note 3) | D31: =+D11 -> Effort To Be Performed By The Prime (P) or Subcontractor (S) (Note 4) | E31: =+E11 -> If Column D=S, Enter Name of Subcontractor(s) (Note 5) | F31: =+F11 -> FTEs (Note 6) | G31: =+G11 -> Total Productive Hours (Note 7) | H31: =+H11 -> Hourly Base Pay Rate (Note 8) | ... R31: =+R11 -> Wrap Rate
A32: =+A12 -> a | B32: =+B12 -> b | C32: =+C12 -> c | D32: =+D12 -> d | E32: =+E12 -> e | F32: =+F12 -> f | G32: =+G12 -> g | H32: =+H12 -> h | ... R32: =+R12 -> r = q/h
A33: =IF('Direct Labor Rate Schedule'!$A$10="","",'Direct Labor Rate Schedule'!$A$10)
A34: =A14 | B34: =B14 -> 0 | C34: =C14 -> Program Manager | D34: Enter P or S | F34: =(G34/AnnualProductiveHours)*(12/11) -> 0 | H34: ='Direct Labor Rate Schedule'!F11 -> 0 | I34: =ROUND((+H34*$I$30),2) -> 0 | J34: =ROUND((+H34*$J$30),2) -> 0 | K34: =+H34+SUM(I34:J34) -> 0 | L34: =ROUND((+G34*K34),2) -> 0 | M34: =ROUND((+L34*$M$30),2) -> 0 | N34: =SUM(L34:M34) -> 0 | O34: =ROUND((+N34*$O$30),2) -> 0 | P34: =SUM(N34:O34) -> 0 | Q34: =IFERROR((+P34/G34),"") | R34: =IFERROR(Q34/H34-1,"")
A35: =A15 | B35: =B15 -> 0 | C35: =C15 -> Senior Analyst | D35: Enter P or S | F35: =(G35/AnnualProductiveHours)*(12/11) -> 0 | H35: ='Direct Labor Rate Schedule'!F12 -> 0 | I35: =ROUND((+H35*$I$30),2) -> 0 | J35: =ROUND((+H35*$J$30),2) -> 0 | K35: =+H35+SUM(I35:J35) -> 0 | L35: =ROUND((+G35*K35),2) -> 0 | M35: =ROUND((+L35*$M$30),2) -> 0 | N35: =SUM(L35:M35) -> 0 | O35: =ROUND((+N35*$O$30),2) -> 0 | P35: =SUM(N35:O35) -> 0 | Q35: =IFERROR((+P35/G35),"") | R35: =IFERROR(Q35/H35-1,"")
A36: =A16 | B36: =B16 -> 0 | C36: =C16 -> Analyst | D36: Enter P or S | F36: =(G36/AnnualProductiveHours)*(12/11) -> 0 | H36: ='Direct Labor Rate Schedule'!F13 -> 0 | I36: =ROUND((+H36*$I$30),2) -> 0 | J36: =ROUND((+H36*$J$30),2) -> 0 | K36: =+H36+SUM(I36:J36) -> 0 | L36: =ROUND((+G36*K36),2) -> 0 | M36: =ROUND((+L36*$M$30),2) -> 0 | N36: =SUM(L36:M36) -> 0 | O36: =ROUND((+N36*$O$30),2) -> 0 | P36: =SUM(N36:O36) -> 0 | Q36: =IFERROR((+P36/G36),"") | R36: =IFERROR(Q36/H36-1,"")
A37: =A17 | B37: =B17 -> 0 | C37: =C17 -> Junior Analyst | D37: Enter P or S | F37: =(G37/AnnualProductiveHours)*(12/11) -> 0 | H37: ='Direct Labor Rate Schedule'!F14 -> 0 | I37: =ROUND((+H37*$I$30),2) -> 0 | J37: =ROUND((+H37*$J$30),2) -> 0 | K37: =+H37+SUM(I37:J37) -> 0 | L37: =ROUND((+G37*K37),2) -> 0 | M37: =ROUND((+L37*$M$30),2) -> 0 | N37: =SUM(L37:M37) -> 0 | O37: =ROUND((+N37*$O$30),2) -> 0 | P37: =SUM(N37:O37) -> 0 | Q37: =IFERROR((+P37/G37),"") | R37: =IFERROR(Q37/H37-1,"")
A38: =A18 | B38: =B18 -> 0 | C38: =C18 -> Senior Operations Research Analyst | D38: Enter P or S | F38: =(G38/AnnualProductiveHours)*(12/11) -> 0 | H38: ='Direct Labor Rate Schedule'!F15 -> 0 | I38: =ROUND((+H38*$I$30),2) -> 0 | J38: =ROUND((+H38*$J$30),2) -> 0 | K38: =+H38+SUM(I38:J38) -> 0 | L38: =ROUND((+G38*K38),2) -> 0 | M38: =ROUND((+L38*$M$30),2) -> 0 | N38: =SUM(L38:M38) -> 0 | O38: =ROUND((+N38*$O$30),2) -> 0 | P38: =SUM(N38:O38) -> 0 | Q38: =IFERROR((+P38/G38),"") | R38: =IFERROR(Q38/H38-1,"")
A39: =A19 | B39: =B19 -> 0 | C39: =C19 -> Operations Research Analyst | D39: Enter P or S | F39: =(G39/AnnualProductiveHours)*(12/11) -> 0 | H39: ='Direct Labor Rate Schedule'!F16 -> 0 | I39: =ROUND((+H39*$I$30),2) -> 0 | J39: =ROUND((+H39*$J$30),2) -> 0 | K39: =+H39+SUM(I39:J39) -> 0 | L39: =ROUND((+G39*K39),2) -> 0 | M39: =ROUND((+L39*$M$30),2) -> 0 | N39: =SUM(L39:M39) -> 0 | O39: =ROUND((+N39*$O$30),2) -> 0 | P39: =SUM(N39:O39) -> 0 | Q39: =IFERROR((+P39/G39),"") | R39: =IFERROR(Q39/H39-1,"")
A40: =A20 | B40: =B20 -> 0 | C40: =C20 -> Graphics Design Senior Analyst | D40: Enter P or S | F40: =(G40/AnnualProductiveHours)*(12/11) -> 0 | H40: ='Direct Labor Rate Schedule'!F17 -> 0 | I40: =ROUND((+H40*$I$30),2) -> 0 | J40: =ROUND((+H40*$J$30),2) -> 0 | K40: =+H40+SUM(I40:J40) -> 0 | L40: =ROUND((+G40*K40),2) -> 0 | M40: =ROUND((+L40*$M$30),2) -> 0 | N40: =SUM(L40:M40) -> 0 | O40: =ROUND((+N40*$O$30),2) -> 0 | P40: =SUM(N40:O40) -> 0 | Q40: =IFERROR((+P40/G40),"") | R40: =IFERROR(Q40/H40-1,"")
A41: =A21 | B41: =B21 -> 0 | C41: =C21 -> Force Documentation Senior Analyst | D41: Enter P or S | F41: =(G41/AnnualProductiveHours)*(12/11) -> 0 | H41: ='Direct Labor Rate Schedule'!F18 -> 0 | I41: =ROUND((+H41*$I$30),2) -> 0 | J41: =ROUND((+H41*$J$30),2) -> 0 | K41: =+H41+SUM(I41:J41) -> 0 | L41: =ROUND((+G41*K41),2) -> 0 | M41: =ROUND((+L41*$M$30),2) -> 0 | N41: =SUM(L41:M41) -> 0 | O41: =ROUND((+N41*$O$30),2) -> 0 | P41: =SUM(N41:O41) -> 0 | Q41: =IFERROR((+P41/G41),"") | R41: =IFERROR(Q41/H41-1,"")
A42: =A22 | B42: =B22 -> 0 | C42: =C22 -> 0 | D42: Enter P or S | F42: =(G42/AnnualProductiveHours)*(12/11) -> 0 | H42: ='Direct Labor Rate Schedule'!F19 -> 0 | I42: =ROUND((+H42*$I$30),2) -> 0 | J42: =ROUND((+H42*$J$30),2) -> 0 | K42: =+H42+SUM(I42:J42) -> 0 | L42: =ROUND((+G42*K42),2) -> 0 | M42: =ROUND((+L42*$M$30),2) -> 0 | N42: =SUM(L42:M42) -> 0 | O42: =ROUND((+N42*$O$30),2) -> 0 | P42: =SUM(N42:O42) -> 0 | Q42: =IFERROR((+P42/G42),"") | R42: =IFERROR(Q42/H42-1,"")
...

Sheet Phase-in & OES 52.217-8 Labor
A1: Labor Cost Detail Spreadsheet
A2: ="Solicitation Number: "&Instructions!H9&"" -> Solicitation Number: W91CRB-25-R-0002
A3: ="Name of Action: "&Instructions!H10 -> Name of Action: Force Development
A4: ="Prime Contractor/Subcontractor Name/Division: "&Instructions!H15 -> Prime Contractor/Subcontractor Name/Division:
A5: ="Period of Performance: "&Instructions!H11 -> Period of Performance:
A6: ="Date of Proposal:"&IF(ISBLANK(Instructions!H18)," TBD",(TEXT(Instructions!H18," mm/dd/yyyy"))) -> Date of Proposal: TBD
A7: ="Annual Productive Hours: "&AnnualProductiveHours -> Annual Productive Hours: 1920
G9: Direct Labor | I9: Indirect Cost
C10: CLIN 0001-1 Transition-In/Phase-In (1 Month) | I10: ='Indirect Rate Summary'!C10 -> 0 | J10: ='Indirect Rate Summary'!D10 -> 0 | M10: ='Indirect Rate Summary'!E10 -> 0 | O10: ='Indirect Rate Summary'!F10 -> 0
A11: Location (Note 1) | B11: Labor Type (Note 2) | C11: Labor Categories (Note 3) | D11: Effort To Be Performed By The Prime (P) or Subcontractor (S) (Note 4) | E11: If Column D=S, Enter Name of Subcontractor(s) (Note 5) | F11: FTEs (Note 6) | G11: Total Productive Hours (Note 7) | H11: Hourly Base Pay Rate (Note 8) | I11: Fringe (Note 9) | J11: Overhead (Note 10) | K11: Prime/Sub Hourly Rate Before Application Of Prime G&A & Fee (IF Col C=S Enter Sub Rate) (Note 11) | L11: Total Prime & Sub Labor Before Prime G&A & Fee | M11: G&A (Note 12) | N11: Total Cost | O11: Fee | P11: Total Price | Q11: Proposal Fully Burdened Hourly Billing Rate | R11: Wrap Rate
A12: a | B12: b | C12: c | D12: d | E12: e | F12: f | G12: g | H12: h | I12: i | J12: j | K12: k = h + i + j | L12: l = g x k | M12: m | N12: n = l + o | O12: o | P12: p = n + o | Q12: q = p/g | R12: r = q/h
A13: =IF('Direct Labor Rate Schedule'!$A$10="","",'Direct Labor Rate Schedule'!$A$10)
A14: =IF('Direct Labor Rate Schedule'!B18="","",'Direct Labor Rate Schedule'!B11) | B14: ='Direct Labor Rate Schedule'!C11 -> 0 | C14: ='Direct Labor Rate Schedule'!A11 -> Program Manager | D14: Enter P or S | F14: =(G14/AnnualProductiveHours) -> 0.08125 | G14: 156 | H14: ='Direct Labor Rate Schedule'!F11 -> 0 | I14: =ROUND((+H14*$I$10),2) -> 0 | J14: =ROUND((+H14*$J$10),2) -> 0 | K14: =+H14+SUM(I14:J14) -> 0 | L14: =ROUND((+G14*K14),2) -> 0 | M14: =ROUND((+L14*$M$10),2) -> 0 | N14: =SUM(L14:M14) -> 0 | O14: =ROUND((+N14*$O$10),2) -> 0 | P14: =SUM(N14:O14) -> 0 | Q14: =IFERROR((+P14/G14),"") -> 0 | R14: =IFERROR(Q14/H14-1,"")
A15: =IF('Direct Labor Rate Schedule'!B19="","",'Direct Labor Rate Schedule'!B12) | B15: ='Direct Labor Rate Schedule'!C12 -> 0 | C15: ='Direct Labor Rate Schedule'!A12 -> Senior Analyst | D15: Enter P or S | F15: =(G15/AnnualProductiveHours) -> 1.05625 | G15: 2028 | H15: ='Direct Labor Rate Schedule'!F12 -> 0 | I15: =ROUND((+H15*$I$10),2) -> 0 | J15: =ROUND((+H15*$J$10),2) -> 0 | K15: =+H15+SUM(I15:J15) -> 0 | L15: =ROUND((+G15*K15),2) -> 0 | M15: =ROUND((+L15*$M$10),2) -> 0 | N15: =SUM(L15:M15) -> 0 | O15: =ROUND((+N15*$O$10),2) -> 0 | P15: =SUM(N15:O15) -> 0 | Q15: =IFERROR((+P15/G15),"") -> 0 | R15: =IFERROR(Q15/H15-1,"")
A16: =IF('Direct Labor Rate Schedule'!B20="","",'Direct Labor Rate Schedule'!B13) | B16: ='Direct Labor Rate Schedule'!C13 -> 0 | C16: ='Direct Labor Rate Schedule'!A13 -> Analyst | D16: Enter P or S | F16: =(G16/AnnualProductiveHours) -> 0 | G16: 0 | H16: ='Direct Labor Rate Schedule'!F13 -> 0 | I16: =ROUND((+H16*$I$10),2) -> 0 | J16: =ROUND((+H16*$J$10),2) -> 0 | K16: =+H16+SUM(I16:J16) -> 0 | L16: =ROUND((+G16*K16),2) -> 0 | M16: =ROUND((+L16*$M$10),2) -> 0 | N16: =SUM(L16:M16) -> 0 | O16: =ROUND((+N16*$O$10),2) -> 0 | P16: =SUM(N16:O16) -> 0 | Q16: =IFERROR((+P16/G16),"") | R16: =IFERROR(Q16/H16-1,"")
A17: =IF('Direct Labor Rate Schedule'!B21="","",'Direct Labor Rate Schedule'!B14) | B17: ='Direct Labor Rate Schedule'!C14 -> 0 | C17: ='Direct Labor Rate Schedule'!A14 -> Junior Analyst | D17: Enter P or S | F17: =(G17/AnnualProductiveHours) -> 0 | G17: 0 | H17: ='Direct Labor Rate Schedule'!F14 -> 0 | I17: =ROUND((+H17*$I$10),2) -> 0 | J17: =ROUND((+H17*$J$10),2) -> 0 | K17: =+H17+SUM(I17:J17) -> 0 | L17: =ROUND((+G17*K17),2) -> 0 | M17: =ROUND((+L17*$M$10),2) -> 0 | N17: =SUM(L17:M17) -> 0 | O17: =ROUND((+N17*$O$10),2) -> 0 | P17: =SUM(N17:O17) -> 0 | Q17: =IFERROR((+P17/G17),"") | R17: =IFERROR(Q17/H17-1,"")
A18: =IF('Direct Labor Rate Schedule'!B22="","",'Direct Labor Rate Schedule'!B15) | B18: ='Direct Labor Rate Schedule'!C15 -> 0 | C18: ='Direct Labor Rate Schedule'!A15 -> Senior Operations Research Analyst | D18: Enter P or S | F18: =(G18/AnnualProductiveHours) -> 0.08125 | G18: 156 | H18: ='Direct Labor Rate Schedule'!F15 -> 0 | I18: =ROUND((+H18*$I$10),2) -> 0 | J18: =ROUND((+H18*$J$10),2) -> 0 | K18: =+H18+SUM(I18:J18) -> 0 | L18: =ROUND((+G18*K18),2) -> 0 | M18: =ROUND((+L18*$M$10),2) -> 0 | N18: =SUM(L18:M18) -> 0 | O18: =ROUND((+N18*$O$10),2) -> 0 | P18: =SUM(N18:O18) -> 0 | Q18: =IFERROR((+P18/G18),"") -> 0 | R18: =IFERROR(Q18/H18-1,"")
A19: =IF('Direct Labor Rate Schedule'!B23="","",'Direct Labor Rate Schedule'!B16) | B19: ='Direct Labor Rate Schedule'!C16 -> 0 | C19: ='Direct Labor Rate Schedule'!A16 -> Operations Research Analyst | D19: Enter P or S | F19: =(G19/AnnualProductiveHours) -> 0 | G19: 0 | H19: ='Direct Labor Rate Schedule'!F16 -> 0 | I19: =ROUND((+H19*$I$10),2) -> 0 | J19: =ROUND((+H19*$J$10),2) -> 0 | K19: =+H19+SUM(I19:J19) -> 0 | L19: =ROUND((+G19*K19),2) -> 0 | M19: =ROUND((+L19*$M$10),2) -> 0 | N19: =SUM(L19:M19) -> 0 | O19: =ROUND((+N19*$O$10),2) -> 0 | P19: =SUM(N19:O19) -> 0 | Q19: =IFERROR((+P19/G19),"") | R19: =IFERROR(Q19/H19-1,"")
A20: =IF('Direct Labor Rate Schedule'!B24="","",'Direct Labor Rate Schedule'!B17) | B20: ='Direct Labor Rate Schedule'!C17 -> 0 | C20: ='Direct Labor Rate Schedule'!A17 -> Graphics Design Senior Analyst | D20: Enter P or S | F20: =(G20/AnnualProductiveHours) -> 0.08125 | G20: 156 | H20: ='Direct Labor Rate Schedule'!F17 -> 0 | I20: =ROUND((+H20*$I$10),2) -> 0 | J20: =ROUND((+H20*$J$10),2) -> 0 | K20: =+H20+SUM(I20:J20) -> 0 | L20: =ROUND((+G20*K20),2) -> 0 | M20: =ROUND((+L20*$M$10),2) -> 0 | N20: =SUM(L20:M20) -> 0 | O20: =ROUND((+N20*$O$10),2) -> 0 | P20: =SUM(N20:O20) -> 0 | Q20: =IFERROR((+P20/G20),"") -> 0 | R20: =IFERROR(Q20/H20-1,"")
A21: =IF('Direct Labor Rate Schedule'!B25="","",'Direct Labor Rate Schedule'!B18) | B21: ='Direct Labor Rate Schedule'!C18 -> 0 | C21: ='Direct Labor Rate Schedule'!A18 -> Force Documentation Senior Analyst | D21: Enter P or S | F21: =(G21/AnnualProductiveHours) -> 0.08125 | G21: 156 | H21: ='Direct Labor Rate Schedule'!F18 -> 0 | I21: =ROUND((+H21*$I$10),2) -> 0 | J21: =ROUND((+H21*$J$10),2) -> 0 | K21: =+H21+SUM(I21:J21) -> 0 | L21: =ROUND((+G21*K21),2) -> 0 | M21: =ROUND((+L21*$M$10),2) -> 0 | N21: =SUM(L21:M21) -> 0 | O21: =ROUND((+N21*$O$10),2) -> 0 | P21: =SUM(N21:O21) -> 0 | Q21: =IFERROR((+P21/G21),"") -> 0 | R21: =IFERROR(Q21/H21-1,"")
A22: =IF('Direct Labor Rate Schedule'!B26="","",'Direct Labor Rate Schedule'!B19) | B22: ='Direct Labor Rate Schedule'!C19 -> 0 | C22: ='Direct Labor Rate Schedule'!A19 -> 0 | D22: Enter P or S | F22: =(G22/AnnualProductiveHours) -> 0 | G22: 0 | H22: ='Direct Labor Rate Schedule'!F19 -> 0 | I22: =ROUND((+H22*$I$10),2) -> 0 | J22: =ROUND((+H22*$J$10),2) -> 0 | K22: =+H22+SUM(I22:J22) -> 0 | L22: =ROUND((+G22*K22),2) -> 0 | M22: =ROUND((+L22*$M$10),2) -> 0 | N22: =SUM(L22:M22) -> 0 | O22: =ROUND((+N22*$O$10),2) -> 0 | P22: =SUM(N22:O22) -> 0 | Q22: =IFERROR((+P22/G22),"") | R22: =IFERROR(Q22/H22-1,"")
A23: =IF('Direct Labor Rate Schedule'!B27="","",'Direct Labor Rate Schedule'!B20) | B23: ='Direct Labor Rate Schedule'!C20 -> 0 | C23: ='Direct Labor Rate Schedule'!A20 -> 0 | D23: Enter P or S | F23: =(G23/AnnualProductiveHours) -> 0 | G23: 0 | H23: ='Direct Labor Rate Schedule'!F20 -> 0 | I23: =ROUND((+H23*$I$10),2) -> 0 | J23: =ROUND((+H23*$J$10),2) -> 0 | K23: =+H23+SUM(I23:J23) -> 0 | L23: =ROUND((+G23*K23),2) -> 0 | M23: =ROUND((+L23*$M$10),2) -> 0 | N23: =SUM(L23:M23) -> 0 | O23: =ROUND((+N23*$O$10),2) -> 0 | P23: =SUM(N23:O23) -> 0 | Q23: =IFERROR((+P23/G23),"") | R23: =IFERROR(Q23/H23-1,"")
A24: =IF('Direct Labor Rate Schedule'!B28="","",'Direct Labor Rate Schedule'!B21) | B24: ='Direct Labor Rate Schedule'!C21 -> 0 | C24: ='Direct Labor Rate Schedule'!A21 -> 0 | D24: Enter P or S | F24: =(G24/AnnualProductiveHours) -> 0 | G24: 0 | H24: ='Direct Labor Rate Schedule'!F21 -> 0 | I24: =ROUND((+H24*$I$10),2) -> 0 | J24: =ROUND((+H24*$J$10),2) -> 0 | K24: =+H24+SUM(I24:J24) -> 0 | L24: =ROUND((+G24*K24),2) -> 0 | M24: =ROUND((+L24*$M$10),2) -> 0 | N24: =SUM(L24:M24) -> 0 | O24: =ROUND((+N24*$O$10),2) -> 0 | P24: =SUM(N24:O24) -> 0 | Q24: =IFERROR((+P24/G24),"") | R24: =IFERROR(Q24/H24-1,"")
A25: =IF('Direct Labor Rate Schedule'!B29="","",'Direct Labor Rate Schedule'!B22) | B25: ='Direct Labor Rate Schedule'!C22 -> 0 | C25: ='Direct Labor Rate Schedule'!A22 -> 0 | D25: Enter P or S | F25: =(G25/AnnualProductiveHours) -> 0 | G25: 0 | H25: ='Direct Labor Rate Schedule'!F22 -> 0 | I25: =ROUND((+H25*$I$10),2) -> 0 | J25: =ROUND((+H25*$J$10),2) -> 0 | K25: =+H25+SUM(I25:J25) -> 0 | L25: =ROUND((+G25*K25),2) -> 0 | M25: =ROUND((+L25*$M$10),2) -> 0 | N25: =SUM(L25:M25) -> 0 | O25: =ROUND((+N25*$O$10),2) -> 0 | P25: =SUM(N25:O25) -> 0 | Q25: =IFERROR((+P25/G25),"") | R25: =IFERROR(Q25/H25-1,"")
A26: Total: | F26: =SUM(F14:F25) -> 1.38125 | G26: =SUM(G14:G25) -> 2652 | H26: =SUMPRODUCT(H14:H25,$G14:$G25) -> 0 | I26: =SUMPRODUCT(I14:I25,$G14:$G25) -> 0 | J26: =SUMPRODUCT(J14:J25,$G14:$G25) -> 0 | K26: =SUMPRODUCT(K14:K25,$G14:$G25) -> 0 | L26: =SUM(L14:L25) -> 0 | M26: =SUM(M14:M25) -> 0 | N26: =SUM(N14:N25) -> 0 | O26: =SUM(O14:O25) -> 0 | P26: =SUM(P14:P25) -> 0 | Q26: =SUMPRODUCT(Q14:Q25,$G14:$G25) -> 0
A27: Weighted Average: | G27: =G26/SUM(F14:F25) -> 1920 | H27: =H26/$G26 -> 0 | I27: =I26/$G26 -> 0 | J27: =J26/$G26 -> 0 | K27: =K26/$G26 -> 0 | L27: =L26/$G26 -> 0 | M27: =M26/$G26 -> 0 | N27: =N26/$G26 -> 0 | O27: =O26/$G26 -> 0 | ... Q27: =Q26/$G26 -> 0 | R27: =Q27/H27 -> #DIV/0!
G29: Direct Cost | I29: Indirect Cost
I30: ='Indirect Rate Summary'!C10 -> 0 | J30: ='Indirect Rate Summary'!D10 -> 0 | M30: ='Indirect Rate Summary'!E10 -> 0 | O30: ='Indirect Rate Summary'!F10 -> 0
A31: =+A11 -> Location (Note 1) | B31: =+B11 -> Labor Type (Note 2) | C31: =+C11 -> Labor Categories (Note 3) | D31: =+D11 -> Effort To Be Performed By The Prime (P) or Subcontractor (S) (Note 4) | E31: =+E11 -> If Column D=S, Enter Name of Subcontractor(s) (Note 5) | F31: =+F11 -> FTEs (Note 6) | G31: =+G11 -> Total Productive Hours (Note 7) | H31: =+H11 -> Hourly Base Pay Rate (Note 8) | ... R31: =+R11 -> Wrap Rate
A32: =+A12 -> a | B32: =+B12 -> b | C32: =+C12 -> c | D32: =+D12 -> d | E32: =+E12 -> e | F32: =+F12 -> f | G32: =+G12 -> g | H32: =+H12 -> h | ... R32: =+R12 -> r = q/h
A33: =IF('Direct Labor Rate Schedule'!$A$10="","",'Direct Labor Rate Schedule'!$A$10)
A34: =A14 | B34: =B14 -> 0 | C34: =C14 -> Program Manager | D34: Enter P or S | F34: =(G34/AnnualProductiveHours)*(12/11) -> 0 | H34: ='Direct Labor Rate Schedule'!F11 -> 0 | I34: =ROUND((+H34*$I$30),2) -> 0 | J34: =ROUND((+H34*$J$30),2) -> 0 | K34: =+H34+SUM(I34:J34) -> 0 | L34: =ROUND((+G34*K34),2) -> 0 | M34: =ROUND((+L34*$M$30),2) -> 0 | N34: =SUM(L34:M34) -> 0 | O34: =ROUND((+N34*$O$30),2) -> 0 | P34: =SUM(N34:O34) -> 0 | Q34: =IFERROR((+P34/G34),"") | R34: =IFERROR(Q34/H34-1,"")
A35: =A15 | B35: =B15 -> 0 | C35: =C15 -> Senior Analyst | D35: Enter P or S | F35: =(G35/AnnualProductiveHours)*(12/11) -> 0 | H35: ='Direct Labor Rate Schedule'!F12 -> 0 | I35: =ROUND((+H35*$I$30),2) -> 0 | J35: =ROUND((+H35*$J$30),2) -> 0 | K35: =+H35+SUM(I35:J35) -> 0 | L35: =ROUND((+G35*K35),2) -> 0 | M35: =ROUND((+L35*$M$30),2) -> 0 | N35: =SUM(L35:M35) -> 0 | O35: =ROUND((+N35*$O$30),2) -> 0 | P35: =SUM(N35:O35) -> 0 | Q35: =IFERROR((+P35/G35),"") | R35: =IFERROR(Q35/H35-1,"")
A36: =A16 | B36: =B16 -> 0 | C36: =C16 -> Analyst | D36: Enter P or S | F36: =(G36/AnnualProductiveHours)*(12/11) -> 0 | H36: ='Direct Labor Rate Schedule'!F13 -> 0 | I36: =ROUND((+H36*$I$30),2) -> 0 | J36: =ROUND((+H36*$J$30),2) -> 0 | K36: =+H36+SUM(I36:J36) -> 0 | L36: =ROUND((+G36*K36),2) -> 0 | M36: =ROUND((+L36*$M$30),2) -> 0 | N36: =SUM(L36:M36) -> 0 | O36: =ROUND((+N36*$O$30),2) -> 0 | P36: =SUM(N36:O36) -> 0 | Q36: =IFERROR((+P36/G36),"") | R36: =IFERROR(Q36/H36-1,"")
A37: =A17 | B37: =B17 -> 0 | C37: =C17 -> Junior Analyst | D37: Enter P or S | F37: =(G37/AnnualProductiveHours)*(12/11) -> 0 | H37: ='Direct Labor Rate Schedule'!F14 -> 0 | I37: =ROUND((+H37*$I$30),2) -> 0 | J37: =ROUND((+H37*$J$30),2) -> 0 | K37: =+H37+SUM(I37:J37) -> 0 | L37: =ROUND((+G37*K37),2) -> 0 | M37: =ROUND((+L37*$M$30),2) -> 0 | N37: =SUM(L37:M37) -> 0 | O37: =ROUND((+N37*$O$30),2) -> 0 | P37: =SUM(N37:O37) -> 0 | Q37: =IFERROR((+P37/G37),"") | R37: =IFERROR(Q37/H37-1,"")
A38: =A18 | B38: =B18 -> 0 | C38: =C18 -> Senior Operations Research Analyst | D38: Enter P or S | F38: =(G38/AnnualProductiveHours)*(12/11) -> 0 | H38: ='Direct Labor Rate Schedule'!F15 -> 0 | I38: =ROUND((+H38*$I$30),2) -> 0 | J38: =ROUND((+H38*$J$30),2) -> 0 | K38: =+H38+SUM(I38:J38) -> 0 | L38: =ROUND((+G38*K38),2) -> 0 | M38: =ROUND((+L38*$M$30),2) -> 0 | N38: =SUM(L38:M38) -> 0 | O38: =ROUND((+N38*$O$30),2) -> 0 | P38: =SUM(N38:O38) -> 0 | Q38: =IFERROR((+P38/G38),"") | R38: =IFERROR(Q38/H38-1,"")
